ERROR:root:Error: Тестовое исключение
ERROR:root:Error: Тестовое исключение
2023-05-08 18:57:15 - Error: Тестовое исключение
2023-05-08 18:58:06 - Error: Тестовое исключение
2023-05-08 19:53:44 - Error: HTTPSConnectionPool(host='api.telegram.org', port=443): Read timed out. (read timeout=25)
2023-05-08 21:00:34 - Error: list indices must be integers or slices, not str
2023-05-08 21:02:49 - Error: 'dict' object has no attribute 'tasks'
2023-05-08 21:09:54 - Error: list indices must be integers or slices, not str
2023-05-08 21:14:08 - Error: '_io.BufferedReader' object has no attribute 'get'
2023-05-08 21:16:12 - Error: 'bytes' object has no attribute 'get'
2023-05-08 21:19:48 - Error: 'bytes' object has no attribute 'get'
2023-05-08 21:21:56 - Error: Failed. Response status: 402. Response message: Payment Required. Error message: {"message":"You have started too many jobs at once","code":"PARALLEL_JOB_LIMIT_EXCEEDED"}
2023-05-08 21:33:56 - Error: create_document() missing 1 required positional argument: 'file_format'
2023-05-08 21:37:41 - Error: [Errno 2] No such file or directory: 'output_files/title_page_6260404903.pdf'
2023-05-09 00:39:25 - Threaded polling exception: A request to the Telegram API was unsuccessful. Error code: 400. Description: Bad Request: can't parse entities: Can't find end tag corresponding to start tag b
2023-05-09 00:39:25 - Exception traceback:
Traceback (most recent call last):
  File "/Users/shapovv/PycharmProjects/Radost/venv/lib/python3.9/site-packages/telebot/__init__.py", line 1074, in __threaded_polling
    self.worker_pool.raise_exceptions()
  File "/Users/shapovv/PycharmProjects/Radost/venv/lib/python3.9/site-packages/telebot/util.py", line 147, in raise_exceptions
    raise self.exception_info
  File "/Users/shapovv/PycharmProjects/Radost/venv/lib/python3.9/site-packages/telebot/util.py", line 90, in run
    task(*args, **kwargs)
  File "/Users/shapovv/PycharmProjects/Radost/venv/lib/python3.9/site-packages/telebot/__init__.py", line 6720, in _run_middlewares_and_handler
    result = handler['function'](message)
  File "/Users/shapovv/PycharmProjects/Radost/bot_test.py", line 182, in document_template_handler
    bot.send_message(call.message.chat.id,
  File "/Users/shapovv/PycharmProjects/Radost/venv/lib/python3.9/site-packages/telebot/__init__.py", line 1549, in send_message
    apihelper.send_message(
  File "/Users/shapovv/PycharmProjects/Radost/venv/lib/python3.9/site-packages/telebot/apihelper.py", line 264, in send_message
    return _make_request(token, method_url, params=payload, method='post')
  File "/Users/shapovv/PycharmProjects/Radost/venv/lib/python3.9/site-packages/telebot/apihelper.py", line 162, in _make_request
    json_result = _check_result(method_name, result)
  File "/Users/shapovv/PycharmProjects/Radost/venv/lib/python3.9/site-packages/telebot/apihelper.py", line 189, in _check_result
    raise ApiTelegramException(method_name, result, result_json)
telebot.apihelper.ApiTelegramException: A request to the Telegram API was unsuccessful. Error code: 400. Description: Bad Request: can't parse entities: Can't find end tag corresponding to start tag b

2023-05-09 00:39:58 - Threaded polling exception: A request to the Telegram API was unsuccessful. Error code: 400. Description: Bad Request: can't parse entities: Can't find end tag corresponding to start tag b
2023-05-09 00:39:58 - Exception traceback:
Traceback (most recent call last):
  File "/Users/shapovv/PycharmProjects/Radost/venv/lib/python3.9/site-packages/telebot/__init__.py", line 1074, in __threaded_polling
    self.worker_pool.raise_exceptions()
  File "/Users/shapovv/PycharmProjects/Radost/venv/lib/python3.9/site-packages/telebot/util.py", line 147, in raise_exceptions
    raise self.exception_info
  File "/Users/shapovv/PycharmProjects/Radost/venv/lib/python3.9/site-packages/telebot/util.py", line 90, in run
    task(*args, **kwargs)
  File "/Users/shapovv/PycharmProjects/Radost/venv/lib/python3.9/site-packages/telebot/__init__.py", line 6720, in _run_middlewares_and_handler
    result = handler['function'](message)
  File "/Users/shapovv/PycharmProjects/Radost/bot_test.py", line 182, in document_template_handler
    bot.send_message(call.message.chat.id,
  File "/Users/shapovv/PycharmProjects/Radost/venv/lib/python3.9/site-packages/telebot/__init__.py", line 1549, in send_message
    apihelper.send_message(
  File "/Users/shapovv/PycharmProjects/Radost/venv/lib/python3.9/site-packages/telebot/apihelper.py", line 264, in send_message
    return _make_request(token, method_url, params=payload, method='post')
  File "/Users/shapovv/PycharmProjects/Radost/venv/lib/python3.9/site-packages/telebot/apihelper.py", line 162, in _make_request
    json_result = _check_result(method_name, result)
  File "/Users/shapovv/PycharmProjects/Radost/venv/lib/python3.9/site-packages/telebot/apihelper.py", line 189, in _check_result
    raise ApiTelegramException(method_name, result, result_json)
telebot.apihelper.ApiTelegramException: A request to the Telegram API was unsuccessful. Error code: 400. Description: Bad Request: can't parse entities: Can't find end tag corresponding to start tag b

2023-05-09 01:20:58 - Error: HTTPSConnectionPool(host='api.telegram.org', port=443): Read timed out. (read timeout=25)
2023-05-09 14:43:10 - Threaded polling exception: A request to the Telegram API was unsuccessful. Error code: 400. Description: Bad Request: message is not modified: specified new message content and reply markup are exactly the same as a current content and reply markup of the message
2023-05-09 14:43:10 - Exception traceback:
Traceback (most recent call last):
  File "/Users/shapovv/PycharmProjects/Radost/venv/lib/python3.9/site-packages/telebot/__init__.py", line 1074, in __threaded_polling
    self.worker_pool.raise_exceptions()
  File "/Users/shapovv/PycharmProjects/Radost/venv/lib/python3.9/site-packages/telebot/util.py", line 147, in raise_exceptions
    raise self.exception_info
  File "/Users/shapovv/PycharmProjects/Radost/venv/lib/python3.9/site-packages/telebot/util.py", line 90, in run
    task(*args, **kwargs)
  File "/Users/shapovv/PycharmProjects/Radost/venv/lib/python3.9/site-packages/telebot/__init__.py", line 6720, in _run_middlewares_and_handler
    result = handler['function'](message)
  File "/Users/shapovv/PycharmProjects/Radost/bot_test.py", line 216, in document_template_handler
    update_document_choice_to_inactive(call.message.chat.id, call.message.message_id)
  File "/Users/shapovv/PycharmProjects/Radost/bot_test.py", line 104, in update_document_choice_to_inactive
    bot.edit_message_reply_markup(chat_id=chat_id, message_id=message_id, reply_markup=keyboard)
  File "/Users/shapovv/PycharmProjects/Radost/venv/lib/python3.9/site-packages/telebot/__init__.py", line 3850, in edit_message_reply_markup
    result = apihelper.edit_message_reply_markup(self.token, chat_id, message_id, inline_message_id, reply_markup)
  File "/Users/shapovv/PycharmProjects/Radost/venv/lib/python3.9/site-packages/telebot/apihelper.py", line 1352, in edit_message_reply_markup
    return _make_request(token, method_url, params=payload, method='post')
  File "/Users/shapovv/PycharmProjects/Radost/venv/lib/python3.9/site-packages/telebot/apihelper.py", line 162, in _make_request
    json_result = _check_result(method_name, result)
  File "/Users/shapovv/PycharmProjects/Radost/venv/lib/python3.9/site-packages/telebot/apihelper.py", line 189, in _check_result
    raise ApiTelegramException(method_name, result, result_json)
telebot.apihelper.ApiTelegramException: A request to the Telegram API was unsuccessful. Error code: 400. Description: Bad Request: message is not modified: specified new message content and reply markup are exactly the same as a current content and reply markup of the message

2023-05-09 14:43:12 - Threaded polling exception: A request to the Telegram API was unsuccessful. Error code: 400. Description: Bad Request: message is not modified: specified new message content and reply markup are exactly the same as a current content and reply markup of the message
2023-05-09 14:43:12 - Exception traceback:
Traceback (most recent call last):
  File "/Users/shapovv/PycharmProjects/Radost/venv/lib/python3.9/site-packages/telebot/__init__.py", line 1074, in __threaded_polling
    self.worker_pool.raise_exceptions()
  File "/Users/shapovv/PycharmProjects/Radost/venv/lib/python3.9/site-packages/telebot/util.py", line 147, in raise_exceptions
    raise self.exception_info
  File "/Users/shapovv/PycharmProjects/Radost/venv/lib/python3.9/site-packages/telebot/util.py", line 90, in run
    task(*args, **kwargs)
  File "/Users/shapovv/PycharmProjects/Radost/venv/lib/python3.9/site-packages/telebot/__init__.py", line 6720, in _run_middlewares_and_handler
    result = handler['function'](message)
  File "/Users/shapovv/PycharmProjects/Radost/bot_test.py", line 216, in document_template_handler
    update_document_choice_to_inactive(call.message.chat.id, call.message.message_id)
  File "/Users/shapovv/PycharmProjects/Radost/bot_test.py", line 104, in update_document_choice_to_inactive
    bot.edit_message_reply_markup(chat_id=chat_id, message_id=message_id, reply_markup=keyboard)
  File "/Users/shapovv/PycharmProjects/Radost/venv/lib/python3.9/site-packages/telebot/__init__.py", line 3850, in edit_message_reply_markup
    result = apihelper.edit_message_reply_markup(self.token, chat_id, message_id, inline_message_id, reply_markup)
  File "/Users/shapovv/PycharmProjects/Radost/venv/lib/python3.9/site-packages/telebot/apihelper.py", line 1352, in edit_message_reply_markup
    return _make_request(token, method_url, params=payload, method='post')
  File "/Users/shapovv/PycharmProjects/Radost/venv/lib/python3.9/site-packages/telebot/apihelper.py", line 162, in _make_request
    json_result = _check_result(method_name, result)
  File "/Users/shapovv/PycharmProjects/Radost/venv/lib/python3.9/site-packages/telebot/apihelper.py", line 189, in _check_result
    raise ApiTelegramException(method_name, result, result_json)
telebot.apihelper.ApiTelegramException: A request to the Telegram API was unsuccessful. Error code: 400. Description: Bad Request: message is not modified: specified new message content and reply markup are exactly the same as a current content and reply markup of the message

2023-05-09 14:43:13 - Threaded polling exception: A request to the Telegram API was unsuccessful. Error code: 400. Description: Bad Request: message is not modified: specified new message content and reply markup are exactly the same as a current content and reply markup of the message
2023-05-09 14:43:13 - Exception traceback:
Traceback (most recent call last):
  File "/Users/shapovv/PycharmProjects/Radost/venv/lib/python3.9/site-packages/telebot/__init__.py", line 1074, in __threaded_polling
    self.worker_pool.raise_exceptions()
  File "/Users/shapovv/PycharmProjects/Radost/venv/lib/python3.9/site-packages/telebot/util.py", line 147, in raise_exceptions
    raise self.exception_info
  File "/Users/shapovv/PycharmProjects/Radost/venv/lib/python3.9/site-packages/telebot/util.py", line 90, in run
    task(*args, **kwargs)
  File "/Users/shapovv/PycharmProjects/Radost/venv/lib/python3.9/site-packages/telebot/__init__.py", line 6720, in _run_middlewares_and_handler
    result = handler['function'](message)
  File "/Users/shapovv/PycharmProjects/Radost/bot_test.py", line 216, in document_template_handler
    update_document_choice_to_inactive(call.message.chat.id, call.message.message_id)
  File "/Users/shapovv/PycharmProjects/Radost/bot_test.py", line 104, in update_document_choice_to_inactive
    bot.edit_message_reply_markup(chat_id=chat_id, message_id=message_id, reply_markup=keyboard)
  File "/Users/shapovv/PycharmProjects/Radost/venv/lib/python3.9/site-packages/telebot/__init__.py", line 3850, in edit_message_reply_markup
    result = apihelper.edit_message_reply_markup(self.token, chat_id, message_id, inline_message_id, reply_markup)
  File "/Users/shapovv/PycharmProjects/Radost/venv/lib/python3.9/site-packages/telebot/apihelper.py", line 1352, in edit_message_reply_markup
    return _make_request(token, method_url, params=payload, method='post')
  File "/Users/shapovv/PycharmProjects/Radost/venv/lib/python3.9/site-packages/telebot/apihelper.py", line 162, in _make_request
    json_result = _check_result(method_name, result)
  File "/Users/shapovv/PycharmProjects/Radost/venv/lib/python3.9/site-packages/telebot/apihelper.py", line 189, in _check_result
    raise ApiTelegramException(method_name, result, result_json)
telebot.apihelper.ApiTelegramException: A request to the Telegram API was unsuccessful. Error code: 400. Description: Bad Request: message is not modified: specified new message content and reply markup are exactly the same as a current content and reply markup of the message

2023-05-09 15:03:42 - Threaded polling exception: A request to the Telegram API was unsuccessful. Error code: 400. Description: Bad Request: can't parse inline keyboard button: Text buttons are unallowed in the inline keyboard
2023-05-09 15:03:42 - Exception traceback:
Traceback (most recent call last):
  File "/Users/shapovv/PycharmProjects/Radost/venv/lib/python3.9/site-packages/telebot/__init__.py", line 1074, in __threaded_polling
    self.worker_pool.raise_exceptions()
  File "/Users/shapovv/PycharmProjects/Radost/venv/lib/python3.9/site-packages/telebot/util.py", line 147, in raise_exceptions
    raise self.exception_info
  File "/Users/shapovv/PycharmProjects/Radost/venv/lib/python3.9/site-packages/telebot/util.py", line 90, in run
    task(*args, **kwargs)
  File "/Users/shapovv/PycharmProjects/Radost/venv/lib/python3.9/site-packages/telebot/__init__.py", line 6720, in _run_middlewares_and_handler
    result = handler['function'](message)
  File "/Users/shapovv/PycharmProjects/Radost/bot_test.py", line 154, in finish_handler
    update_buttons_to_inactive(call.message.chat.id, call.message.message_id, document_type)
  File "/Users/shapovv/PycharmProjects/Radost/bot_test.py", line 143, in update_buttons_to_inactive
    bot.edit_message_text("Что вы хотите сделать дальше?", chat_id=chat_id, message_id=message_id,
  File "/Users/shapovv/PycharmProjects/Radost/venv/lib/python3.9/site-packages/telebot/__init__.py", line 3784, in edit_message_text
    result = apihelper.edit_message_text(self.token, text, chat_id, message_id, inline_message_id, parse_mode,
  File "/Users/shapovv/PycharmProjects/Radost/venv/lib/python3.9/site-packages/telebot/apihelper.py", line 1304, in edit_message_text
    return _make_request(token, method_url, params=payload, method='post')
  File "/Users/shapovv/PycharmProjects/Radost/venv/lib/python3.9/site-packages/telebot/apihelper.py", line 162, in _make_request
    json_result = _check_result(method_name, result)
  File "/Users/shapovv/PycharmProjects/Radost/venv/lib/python3.9/site-packages/telebot/apihelper.py", line 189, in _check_result
    raise ApiTelegramException(method_name, result, result_json)
telebot.apihelper.ApiTelegramException: A request to the Telegram API was unsuccessful. Error code: 400. Description: Bad Request: can't parse inline keyboard button: Text buttons are unallowed in the inline keyboard

2023-05-09 15:58:22 - Threaded polling exception: A request to the Telegram API was unsuccessful. Error code: 400. Description: Bad Request: can't parse entities: Can't find end tag corresponding to start tag b
2023-05-09 15:58:22 - Exception traceback:
Traceback (most recent call last):
  File "/Users/shapovv/PycharmProjects/Radost/venv/lib/python3.9/site-packages/telebot/__init__.py", line 1074, in __threaded_polling
    self.worker_pool.raise_exceptions()
  File "/Users/shapovv/PycharmProjects/Radost/venv/lib/python3.9/site-packages/telebot/util.py", line 147, in raise_exceptions
    raise self.exception_info
  File "/Users/shapovv/PycharmProjects/Radost/venv/lib/python3.9/site-packages/telebot/util.py", line 90, in run
    task(*args, **kwargs)
  File "/Users/shapovv/PycharmProjects/Radost/venv/lib/python3.9/site-packages/telebot/__init__.py", line 6720, in _run_middlewares_and_handler
    result = handler['function'](message)
  File "/Users/shapovv/PycharmProjects/Radost/bot_test.py", line 265, in document_template_handler
    bot.send_message(call.message.chat.id,
  File "/Users/shapovv/PycharmProjects/Radost/venv/lib/python3.9/site-packages/telebot/__init__.py", line 1549, in send_message
    apihelper.send_message(
  File "/Users/shapovv/PycharmProjects/Radost/venv/lib/python3.9/site-packages/telebot/apihelper.py", line 264, in send_message
    return _make_request(token, method_url, params=payload, method='post')
  File "/Users/shapovv/PycharmProjects/Radost/venv/lib/python3.9/site-packages/telebot/apihelper.py", line 162, in _make_request
    json_result = _check_result(method_name, result)
  File "/Users/shapovv/PycharmProjects/Radost/venv/lib/python3.9/site-packages/telebot/apihelper.py", line 189, in _check_result
    raise ApiTelegramException(method_name, result, result_json)
telebot.apihelper.ApiTelegramException: A request to the Telegram API was unsuccessful. Error code: 400. Description: Bad Request: can't parse entities: Can't find end tag corresponding to start tag b

2023-05-09 16:12:27 - Error: 760923861
2023-05-09 16:20:04 - Error: 'NoneType' object has no attribute 'startswith'
2023-05-09 23:53:49 - Threaded polling exception: A request to the Telegram API was unsuccessful. Error code: 400. Description: Bad Request: can't parse entities: Unsupported start tag "b/" at byte offset 95
2023-05-09 23:53:49 - Exception traceback:
Traceback (most recent call last):
  File "/Users/shapovv/PycharmProjects/Radost/venv/lib/python3.9/site-packages/telebot/__init__.py", line 1074, in __threaded_polling
    self.worker_pool.raise_exceptions()
  File "/Users/shapovv/PycharmProjects/Radost/venv/lib/python3.9/site-packages/telebot/util.py", line 147, in raise_exceptions
    raise self.exception_info
  File "/Users/shapovv/PycharmProjects/Radost/venv/lib/python3.9/site-packages/telebot/util.py", line 90, in run
    task(*args, **kwargs)
  File "/Users/shapovv/PycharmProjects/Radost/venv/lib/python3.9/site-packages/telebot/__init__.py", line 6720, in _run_middlewares_and_handler
    result = handler['function'](message)
  File "/Users/shapovv/PycharmProjects/Radost/bot_test.py", line 277, in document_template_handler
    bot.send_message(call.message.chat.id,
  File "/Users/shapovv/PycharmProjects/Radost/venv/lib/python3.9/site-packages/telebot/__init__.py", line 1549, in send_message
    apihelper.send_message(
  File "/Users/shapovv/PycharmProjects/Radost/venv/lib/python3.9/site-packages/telebot/apihelper.py", line 264, in send_message
    return _make_request(token, method_url, params=payload, method='post')
  File "/Users/shapovv/PycharmProjects/Radost/venv/lib/python3.9/site-packages/telebot/apihelper.py", line 162, in _make_request
    json_result = _check_result(method_name, result)
  File "/Users/shapovv/PycharmProjects/Radost/venv/lib/python3.9/site-packages/telebot/apihelper.py", line 189, in _check_result
    raise ApiTelegramException(method_name, result, result_json)
telebot.apihelper.ApiTelegramException: A request to the Telegram API was unsuccessful. Error code: 400. Description: Bad Request: can't parse entities: Unsupported start tag "b/" at byte offset 95

2023-05-10 13:43:37 - Error: HTTPSConnectionPool(host='api.telegram.org', port=443): Read timed out. (read timeout=25)
2023-05-10 13:50:55 - Error: HTTPSConnectionPool(host='api.telegram.org', port=443): Read timed out. (read timeout=25)
2023-05-10 15:24:04 - Error: keywords must be strings
2023-05-10 15:24:14 - Error: keywords must be strings
2023-05-10 15:45:00 - Error: [Errno 2] No such file or directory: 'output_files/title_page_Shapovalov_2023.docx'
2023-05-10 15:47:44 - Error: [Errno 2] No such file or directory: 'output_files/title_page_shap_2023.docx'
2023-05-10 15:51:19 - Error: [Errno 2] No such file or directory: 'output_files/title_page_Shapovv_2023.docx'
2023-05-10 15:51:30 - Error: [Errno 2] No such file or directory: 'output_files/title_page_Shapovv_2023.docx'
2023-05-10 15:55:38 - Error: [Errno 2] No such file or directory: 'output_files/title_page_shapovv_2023.pdf'
2023-05-10 15:55:49 - Error: [Errno 2] No such file or directory: 'output_files/title_page_shapovv_2023.pdf'
2023-05-10 16:00:38 - Error: [Errno 2] No such file or directory: 'output_files/title_page_Osip_2025.pdf'
2023-05-10 16:00:48 - Error: [Errno 2] No such file or directory: 'output_files/title_page_Osip_2025.pdf'
2023-05-10 16:00:58 - Error: [Errno 2] No such file or directory: 'output_files/title_page_Osip_2025.pdf'
2023-05-10 16:01:09 - Error: [Errno 2] No such file or directory: 'output_files/title_page_Osip_2025.pdf'
2023-05-10 16:01:29 - Error: [Errno 2] No such file or directory: 'output_files/title_page_Osip_2025.pdf'
2023-05-10 16:28:19 - Error: HTTPSConnectionPool(host='api.telegram.org', port=443): Read timed out. (read timeout=25)
2023-05-10 16:47:23 - Error: 760923861
2023-05-10 18:12:46 - Error: Тестовое исключение
2023-05-10 18:54:47 - Threaded polling exception: A request to the Telegram API was unsuccessful. Error code: 400. Description: Bad Request: BUTTON_DATA_INVALID
2023-05-10 18:54:47 - Exception traceback:
Traceback (most recent call last):
  File "/Users/shapovv/PycharmProjects/Radost/venv/lib/python3.9/site-packages/telebot/__init__.py", line 1074, in __threaded_polling
    self.worker_pool.raise_exceptions()
  File "/Users/shapovv/PycharmProjects/Radost/venv/lib/python3.9/site-packages/telebot/util.py", line 147, in raise_exceptions
    raise self.exception_info
  File "/Users/shapovv/PycharmProjects/Radost/venv/lib/python3.9/site-packages/telebot/util.py", line 90, in run
    task(*args, **kwargs)
  File "/Users/shapovv/PycharmProjects/Radost/bot_test.py", line 56, in save_handler
    next_step_handler(message, chat_steps[message.chat.id])
  File "/Users/shapovv/PycharmProjects/Radost/bot_test.py", line 93, in next_step_handler
    create_document(message, explanatory_note_code_blocks[message.chat.id], 'explanatory_note_maket.docx',
  File "/Users/shapovv/PycharmProjects/Radost/bot_test.py", line 275, in create_document
    ask_for_conversion(message, filename)
  File "/Users/shapovv/PycharmProjects/Radost/bot_test.py", line 209, in ask_for_conversion
    bot.send_message(message.chat.id, 'Хотите конвертировать файл в формат PDF?', reply_markup=markup)
  File "/Users/shapovv/PycharmProjects/Radost/venv/lib/python3.9/site-packages/telebot/__init__.py", line 1549, in send_message
    apihelper.send_message(
  File "/Users/shapovv/PycharmProjects/Radost/venv/lib/python3.9/site-packages/telebot/apihelper.py", line 264, in send_message
    return _make_request(token, method_url, params=payload, method='post')
  File "/Users/shapovv/PycharmProjects/Radost/venv/lib/python3.9/site-packages/telebot/apihelper.py", line 162, in _make_request
    json_result = _check_result(method_name, result)
  File "/Users/shapovv/PycharmProjects/Radost/venv/lib/python3.9/site-packages/telebot/apihelper.py", line 189, in _check_result
    raise ApiTelegramException(method_name, result, result_json)
telebot.apihelper.ApiTelegramException: A request to the Telegram API was unsuccessful. Error code: 400. Description: Bad Request: BUTTON_DATA_INVALID

2023-05-10 19:09:07 - Threaded polling exception: A request to the Telegram API was unsuccessful. Error code: 400. Description: Bad Request: BUTTON_DATA_INVALID
2023-05-10 19:09:07 - Exception traceback:
Traceback (most recent call last):
  File "/Users/shapovv/PycharmProjects/Radost/venv/lib/python3.9/site-packages/telebot/__init__.py", line 1074, in __threaded_polling
    self.worker_pool.raise_exceptions()
  File "/Users/shapovv/PycharmProjects/Radost/venv/lib/python3.9/site-packages/telebot/util.py", line 147, in raise_exceptions
    raise self.exception_info
  File "/Users/shapovv/PycharmProjects/Radost/venv/lib/python3.9/site-packages/telebot/util.py", line 90, in run
    task(*args, **kwargs)
  File "/Users/shapovv/PycharmProjects/Radost/bot_test.py", line 56, in save_handler
    next_step_handler(message, chat_steps[message.chat.id])
  File "/Users/shapovv/PycharmProjects/Radost/bot_test.py", line 93, in next_step_handler
    create_document(message, explanatory_note_code_blocks[message.chat.id], 'explanatory_note_maket.docx',
  File "/Users/shapovv/PycharmProjects/Radost/bot_test.py", line 274, in create_document
    ask_for_conversion(message, filename)
  File "/Users/shapovv/PycharmProjects/Radost/bot_test.py", line 208, in ask_for_conversion
    bot.send_message(message.chat.id, 'Хотите конвертировать файл в формат PDF?', reply_markup=markup)
  File "/Users/shapovv/PycharmProjects/Radost/venv/lib/python3.9/site-packages/telebot/__init__.py", line 1549, in send_message
    apihelper.send_message(
  File "/Users/shapovv/PycharmProjects/Radost/venv/lib/python3.9/site-packages/telebot/apihelper.py", line 264, in send_message
    return _make_request(token, method_url, params=payload, method='post')
  File "/Users/shapovv/PycharmProjects/Radost/venv/lib/python3.9/site-packages/telebot/apihelper.py", line 162, in _make_request
    json_result = _check_result(method_name, result)
  File "/Users/shapovv/PycharmProjects/Radost/venv/lib/python3.9/site-packages/telebot/apihelper.py", line 189, in _check_result
    raise ApiTelegramException(method_name, result, result_json)
telebot.apihelper.ApiTelegramException: A request to the Telegram API was unsuccessful. Error code: 400. Description: Bad Request: BUTTON_DATA_INVALID

2023-05-10 19:09:54 - Error: [Errno 2] No such file or directory: 'output_files/explanatory_note_yak_2020.pdf'
2023-05-10 19:10:21 - Error: [Errno 2] No such file or directory: 'output_files/explanatory_note_yak_2020.pdf'
2023-05-10 19:46:43 - Threaded polling exception: A request to the Telegram API was unsuccessful. Error code: 400. Description: Bad Request: BUTTON_DATA_INVALID
2023-05-10 19:46:43 - Exception traceback:
Traceback (most recent call last):
  File "/Users/shapovv/PycharmProjects/Radost/venv/lib/python3.9/site-packages/telebot/__init__.py", line 1074, in __threaded_polling
    self.worker_pool.raise_exceptions()
  File "/Users/shapovv/PycharmProjects/Radost/venv/lib/python3.9/site-packages/telebot/util.py", line 147, in raise_exceptions
    raise self.exception_info
  File "/Users/shapovv/PycharmProjects/Radost/venv/lib/python3.9/site-packages/telebot/util.py", line 90, in run
    task(*args, **kwargs)
  File "/Users/shapovv/PycharmProjects/Radost/bot_test.py", line 50, in save_handler
    handle_stop(message)
  File "/Users/shapovv/PycharmProjects/Radost/bot_test.py", line 302, in handle_stop
    create_document(message, explanatory_note_code_blocks[message.chat.id], 'explanatory_note_maket.docx',
  File "/Users/shapovv/PycharmProjects/Radost/bot_test.py", line 280, in create_document
    ask_for_conversion(message, filename)
  File "/Users/shapovv/PycharmProjects/Radost/bot_test.py", line 214, in ask_for_conversion
    bot.send_message(message.chat.id, 'Хотите конвертировать файл в формат PDF?', reply_markup=markup)
  File "/Users/shapovv/PycharmProjects/Radost/venv/lib/python3.9/site-packages/telebot/__init__.py", line 1549, in send_message
    apihelper.send_message(
  File "/Users/shapovv/PycharmProjects/Radost/venv/lib/python3.9/site-packages/telebot/apihelper.py", line 264, in send_message
    return _make_request(token, method_url, params=payload, method='post')
  File "/Users/shapovv/PycharmProjects/Radost/venv/lib/python3.9/site-packages/telebot/apihelper.py", line 162, in _make_request
    json_result = _check_result(method_name, result)
  File "/Users/shapovv/PycharmProjects/Radost/venv/lib/python3.9/site-packages/telebot/apihelper.py", line 189, in _check_result
    raise ApiTelegramException(method_name, result, result_json)
telebot.apihelper.ApiTelegramException: A request to the Telegram API was unsuccessful. Error code: 400. Description: Bad Request: BUTTON_DATA_INVALID

2023-05-10 22:23:26 - Threaded polling exception: A request to the Telegram API was unsuccessful. Error code: 400. Description: Bad Request: BUTTON_DATA_INVALID
2023-05-10 22:23:26 - Exception traceback:
Traceback (most recent call last):
  File "/Users/shapovv/PycharmProjects/Radost/venv/lib/python3.9/site-packages/telebot/__init__.py", line 1074, in __threaded_polling
    self.worker_pool.raise_exceptions()
  File "/Users/shapovv/PycharmProjects/Radost/venv/lib/python3.9/site-packages/telebot/util.py", line 147, in raise_exceptions
    raise self.exception_info
  File "/Users/shapovv/PycharmProjects/Radost/venv/lib/python3.9/site-packages/telebot/util.py", line 90, in run
    task(*args, **kwargs)
  File "/Users/shapovv/PycharmProjects/Radost/bot_test.py", line 59, in save_handler
    next_step_handler(message, chat_steps[message.chat.id])
  File "/Users/shapovv/PycharmProjects/Radost/bot_test.py", line 96, in next_step_handler
    create_document(message, explanatory_note_code_blocks[message.chat.id], 'explanatory_note_maket.docx',
  File "/Users/shapovv/PycharmProjects/Radost/bot_test.py", line 288, in create_document
    ask_for_conversion(message, filename)
  File "/Users/shapovv/PycharmProjects/Radost/bot_test.py", line 217, in ask_for_conversion
    bot.send_message(message.chat.id,
  File "/Users/shapovv/PycharmProjects/Radost/venv/lib/python3.9/site-packages/telebot/__init__.py", line 1549, in send_message
    apihelper.send_message(
  File "/Users/shapovv/PycharmProjects/Radost/venv/lib/python3.9/site-packages/telebot/apihelper.py", line 264, in send_message
    return _make_request(token, method_url, params=payload, method='post')
  File "/Users/shapovv/PycharmProjects/Radost/venv/lib/python3.9/site-packages/telebot/apihelper.py", line 162, in _make_request
    json_result = _check_result(method_name, result)
  File "/Users/shapovv/PycharmProjects/Radost/venv/lib/python3.9/site-packages/telebot/apihelper.py", line 189, in _check_result
    raise ApiTelegramException(method_name, result, result_json)
telebot.apihelper.ApiTelegramException: A request to the Telegram API was unsuccessful. Error code: 400. Description: Bad Request: BUTTON_DATA_INVALID

2023-05-10 22:38:07 - Threaded polling exception: A request to the Telegram API was unsuccessful. Error code: 400. Description: Bad Request: BUTTON_DATA_INVALID
2023-05-10 22:38:07 - Exception traceback:
Traceback (most recent call last):
  File "/Users/shapovv/PycharmProjects/Radost/venv/lib/python3.9/site-packages/telebot/__init__.py", line 1074, in __threaded_polling
    self.worker_pool.raise_exceptions()
  File "/Users/shapovv/PycharmProjects/Radost/venv/lib/python3.9/site-packages/telebot/util.py", line 147, in raise_exceptions
    raise self.exception_info
  File "/Users/shapovv/PycharmProjects/Radost/venv/lib/python3.9/site-packages/telebot/util.py", line 90, in run
    task(*args, **kwargs)
  File "/Users/shapovv/PycharmProjects/Radost/bot_test.py", line 58, in save_handler
    next_step_handler(message, chat_steps[message.chat.id])
  File "/Users/shapovv/PycharmProjects/Radost/bot_test.py", line 95, in next_step_handler
    create_document(message, explanatory_note_code_blocks[message.chat.id], 'explanatory_note_maket.docx',
  File "/Users/shapovv/PycharmProjects/Radost/bot_test.py", line 283, in create_document
    ask_for_conversion(message, filename)
  File "/Users/shapovv/PycharmProjects/Radost/bot_test.py", line 212, in ask_for_conversion
    bot.send_message(message.chat.id,
  File "/Users/shapovv/PycharmProjects/Radost/venv/lib/python3.9/site-packages/telebot/__init__.py", line 1549, in send_message
    apihelper.send_message(
  File "/Users/shapovv/PycharmProjects/Radost/venv/lib/python3.9/site-packages/telebot/apihelper.py", line 264, in send_message
    return _make_request(token, method_url, params=payload, method='post')
  File "/Users/shapovv/PycharmProjects/Radost/venv/lib/python3.9/site-packages/telebot/apihelper.py", line 162, in _make_request
    json_result = _check_result(method_name, result)
  File "/Users/shapovv/PycharmProjects/Radost/venv/lib/python3.9/site-packages/telebot/apihelper.py", line 189, in _check_result
    raise ApiTelegramException(method_name, result, result_json)
telebot.apihelper.ApiTelegramException: A request to the Telegram API was unsuccessful. Error code: 400. Description: Bad Request: BUTTON_DATA_INVALID

2023-05-10 22:47:56 - Threaded polling exception: A request to the Telegram API was unsuccessful. Error code: 400. Description: Bad Request: BUTTON_DATA_INVALID
2023-05-10 22:47:56 - Exception traceback:
Traceback (most recent call last):
  File "/Users/shapovv/PycharmProjects/Radost/venv/lib/python3.9/site-packages/telebot/__init__.py", line 1074, in __threaded_polling
    self.worker_pool.raise_exceptions()
  File "/Users/shapovv/PycharmProjects/Radost/venv/lib/python3.9/site-packages/telebot/util.py", line 147, in raise_exceptions
    raise self.exception_info
  File "/Users/shapovv/PycharmProjects/Radost/venv/lib/python3.9/site-packages/telebot/util.py", line 90, in run
    task(*args, **kwargs)
  File "/Users/shapovv/PycharmProjects/Radost/bot_test.py", line 58, in save_handler
    next_step_handler(message, chat_steps[message.chat.id])
  File "/Users/shapovv/PycharmProjects/Radost/bot_test.py", line 95, in next_step_handler
    create_document(message, explanatory_note_code_blocks[message.chat.id], 'explanatory_note_maket.docx',
  File "/Users/shapovv/PycharmProjects/Radost/bot_test.py", line 284, in create_document
    ask_for_conversion(message, filename)
  File "/Users/shapovv/PycharmProjects/Radost/bot_test.py", line 212, in ask_for_conversion
    bot.send_message(message.chat.id,
  File "/Users/shapovv/PycharmProjects/Radost/venv/lib/python3.9/site-packages/telebot/__init__.py", line 1549, in send_message
    apihelper.send_message(
  File "/Users/shapovv/PycharmProjects/Radost/venv/lib/python3.9/site-packages/telebot/apihelper.py", line 264, in send_message
    return _make_request(token, method_url, params=payload, method='post')
  File "/Users/shapovv/PycharmProjects/Radost/venv/lib/python3.9/site-packages/telebot/apihelper.py", line 162, in _make_request
    json_result = _check_result(method_name, result)
  File "/Users/shapovv/PycharmProjects/Radost/venv/lib/python3.9/site-packages/telebot/apihelper.py", line 189, in _check_result
    raise ApiTelegramException(method_name, result, result_json)
telebot.apihelper.ApiTelegramException: A request to the Telegram API was unsuccessful. Error code: 400. Description: Bad Request: BUTTON_DATA_INVALID

2023-05-10 22:48:55 - Threaded polling exception: A request to the Telegram API was unsuccessful. Error code: 400. Description: Bad Request: BUTTON_DATA_INVALID
2023-05-10 22:48:55 - Exception traceback:
Traceback (most recent call last):
  File "/Users/shapovv/PycharmProjects/Radost/venv/lib/python3.9/site-packages/telebot/__init__.py", line 1074, in __threaded_polling
    self.worker_pool.raise_exceptions()
  File "/Users/shapovv/PycharmProjects/Radost/venv/lib/python3.9/site-packages/telebot/util.py", line 147, in raise_exceptions
    raise self.exception_info
  File "/Users/shapovv/PycharmProjects/Radost/venv/lib/python3.9/site-packages/telebot/util.py", line 90, in run
    task(*args, **kwargs)
  File "/Users/shapovv/PycharmProjects/Radost/venv/lib/python3.9/site-packages/telebot/__init__.py", line 6720, in _run_middlewares_and_handler
    result = handler['function'](message)
  File "/Users/shapovv/PycharmProjects/Radost/bot_test.py", line 373, in handle_stop_command
    handle_stop(message)
  File "/Users/shapovv/PycharmProjects/Radost/bot_test.py", line 306, in handle_stop
    create_document(message, explanatory_note_code_blocks[message.chat.id], 'explanatory_note_maket.docx',
  File "/Users/shapovv/PycharmProjects/Radost/bot_test.py", line 284, in create_document
    ask_for_conversion(message, filename)
  File "/Users/shapovv/PycharmProjects/Radost/bot_test.py", line 212, in ask_for_conversion
    bot.send_message(message.chat.id,
  File "/Users/shapovv/PycharmProjects/Radost/venv/lib/python3.9/site-packages/telebot/__init__.py", line 1549, in send_message
    apihelper.send_message(
  File "/Users/shapovv/PycharmProjects/Radost/venv/lib/python3.9/site-packages/telebot/apihelper.py", line 264, in send_message
    return _make_request(token, method_url, params=payload, method='post')
  File "/Users/shapovv/PycharmProjects/Radost/venv/lib/python3.9/site-packages/telebot/apihelper.py", line 162, in _make_request
    json_result = _check_result(method_name, result)
  File "/Users/shapovv/PycharmProjects/Radost/venv/lib/python3.9/site-packages/telebot/apihelper.py", line 189, in _check_result
    raise ApiTelegramException(method_name, result, result_json)
telebot.apihelper.ApiTelegramException: A request to the Telegram API was unsuccessful. Error code: 400. Description: Bad Request: BUTTON_DATA_INVALID

2023-05-10 22:49:42 - Threaded polling exception: A request to the Telegram API was unsuccessful. Error code: 400. Description: Bad Request: BUTTON_DATA_INVALID
2023-05-10 22:49:42 - Exception traceback:
Traceback (most recent call last):
  File "/Users/shapovv/PycharmProjects/Radost/venv/lib/python3.9/site-packages/telebot/__init__.py", line 1074, in __threaded_polling
    self.worker_pool.raise_exceptions()
  File "/Users/shapovv/PycharmProjects/Radost/venv/lib/python3.9/site-packages/telebot/util.py", line 147, in raise_exceptions
    raise self.exception_info
  File "/Users/shapovv/PycharmProjects/Radost/venv/lib/python3.9/site-packages/telebot/util.py", line 90, in run
    task(*args, **kwargs)
  File "/Users/shapovv/PycharmProjects/Radost/bot_test.py", line 58, in save_handler
    next_step_handler(message, chat_steps[message.chat.id])
  File "/Users/shapovv/PycharmProjects/Radost/bot_test.py", line 95, in next_step_handler
    create_document(message, explanatory_note_code_blocks[message.chat.id], 'explanatory_note_maket.docx',
  File "/Users/shapovv/PycharmProjects/Radost/bot_test.py", line 284, in create_document
    ask_for_conversion(message, filename)
  File "/Users/shapovv/PycharmProjects/Radost/bot_test.py", line 212, in ask_for_conversion
    bot.send_message(message.chat.id,
  File "/Users/shapovv/PycharmProjects/Radost/venv/lib/python3.9/site-packages/telebot/__init__.py", line 1549, in send_message
    apihelper.send_message(
  File "/Users/shapovv/PycharmProjects/Radost/venv/lib/python3.9/site-packages/telebot/apihelper.py", line 264, in send_message
    return _make_request(token, method_url, params=payload, method='post')
  File "/Users/shapovv/PycharmProjects/Radost/venv/lib/python3.9/site-packages/telebot/apihelper.py", line 162, in _make_request
    json_result = _check_result(method_name, result)
  File "/Users/shapovv/PycharmProjects/Radost/venv/lib/python3.9/site-packages/telebot/apihelper.py", line 189, in _check_result
    raise ApiTelegramException(method_name, result, result_json)
telebot.apihelper.ApiTelegramException: A request to the Telegram API was unsuccessful. Error code: 400. Description: Bad Request: BUTTON_DATA_INVALID

2023-05-11 00:35:30 - Error: 'NoneType' object has no attribute 'startswith'
2023-05-13 12:10:08 - Error: Тестовое исключение
2023-05-22 20:51:36 - Threaded polling exception: A request to the Telegram API was unsuccessful. Error code: 400. Description: Bad Request: can't parse entities: Can't find end tag corresponding to start tag b
2023-05-22 20:51:36 - Exception traceback:
Traceback (most recent call last):
  File "/Users/shapovv/PycharmProjects/Radost/venv/lib/python3.9/site-packages/telebot/__init__.py", line 1074, in __threaded_polling
    self.worker_pool.raise_exceptions()
  File "/Users/shapovv/PycharmProjects/Radost/venv/lib/python3.9/site-packages/telebot/util.py", line 147, in raise_exceptions
    raise self.exception_info
  File "/Users/shapovv/PycharmProjects/Radost/venv/lib/python3.9/site-packages/telebot/util.py", line 90, in run
    task(*args, **kwargs)
  File "/Users/shapovv/PycharmProjects/Radost/venv/lib/python3.9/site-packages/telebot/__init__.py", line 6720, in _run_middlewares_and_handler
    result = handler['function'](message)
  File "/Users/shapovv/PycharmProjects/Radost/bot_test.py", line 399, in document_template_handler
    bot.send_message(call.message.chat.id,
  File "/Users/shapovv/PycharmProjects/Radost/venv/lib/python3.9/site-packages/telebot/__init__.py", line 1549, in send_message
    apihelper.send_message(
  File "/Users/shapovv/PycharmProjects/Radost/venv/lib/python3.9/site-packages/telebot/apihelper.py", line 264, in send_message
    return _make_request(token, method_url, params=payload, method='post')
  File "/Users/shapovv/PycharmProjects/Radost/venv/lib/python3.9/site-packages/telebot/apihelper.py", line 162, in _make_request
    json_result = _check_result(method_name, result)
  File "/Users/shapovv/PycharmProjects/Radost/venv/lib/python3.9/site-packages/telebot/apihelper.py", line 189, in _check_result
    raise ApiTelegramException(method_name, result, result_json)
telebot.apihelper.ApiTelegramException: A request to the Telegram API was unsuccessful. Error code: 400. Description: Bad Request: can't parse entities: Can't find end tag corresponding to start tag b

2023-05-22 21:23:08 - Error: HTTPSConnectionPool(host='api.telegram.org', port=443): Read timed out. (read timeout=25)
2023-05-22 21:23:08 - Failed to send error message: HTTPSConnectionPool(host='api.telegram.org', port=443): Max retries exceeded with url: /bot6260404903:AAEU0Ax58ULUNvM9rBva_NR4cEIdTelM7OI/sendMessage?chat_id=455162494&text=%D0%9F%D1%80%D0%BE%D0%B8%D0%B7%D0%BE%D1%88%D0%BB%D0%B0+%D0%BE%D1%88%D0%B8%D0%B1%D0%BA%D0%B0%3A+HTTPSConnectionPool%28host%3D%27api.telegram.org%27%2C+port%3D443%29%3A+Read+timed+out.+%28read+timeout%3D25%29 (Caused by NewConnectionError('<urllib3.connection.HTTPSConnection object at 0x104b3a7c0>: Failed to establish a new connection: [Errno 8] nodename nor servname provided, or not known'))
2023-05-22 21:25:46 - Error: HTTPSConnectionPool(host='api.telegram.org', port=443): Max retries exceeded with url: /bot6260404903:AAEU0Ax58ULUNvM9rBva_NR4cEIdTelM7OI/getUpdates?offset=337823247&timeout=20 (Caused by NewConnectionError('<urllib3.connection.HTTPSConnection object at 0x104c4d610>: Failed to establish a new connection: [Errno 8] nodename nor servname provided, or not known'))
2023-05-22 21:25:46 - Failed to send error message: HTTPSConnectionPool(host='api.telegram.org', port=443): Max retries exceeded with url: /bot6260404903:AAEU0Ax58ULUNvM9rBva_NR4cEIdTelM7OI/sendMessage?chat_id=455162494&text=%D0%9F%D1%80%D0%BE%D0%B8%D0%B7%D0%BE%D1%88%D0%BB%D0%B0+%D0%BE%D1%88%D0%B8%D0%B1%D0%BA%D0%B0%3A+HTTPSConnectionPool%28host%3D%27api.telegram.org%27%2C+port%3D443%29%3A+Max+retries+exceeded+with+url%3A+%2Fbot6260404903%3AAAEU0Ax58ULUNvM9rBva_NR4cEIdTelM7OI%2FgetUpdates%3Foffset%3D337823247%26timeout%3D20+%28Caused+by+NewConnectionError%28%27%3Curllib3.connection.HTTPSConnection+object+at+0x104c4d610%3E%3A+Failed+to+establish+a+new+connection%3A+%5BErrno+8%5D+nodename+nor+servname+provided%2C+or+not+known%27%29%29 (Caused by NewConnectionError('<urllib3.connection.HTTPSConnection object at 0x104c4de20>: Failed to establish a new connection: [Errno 8] nodename nor servname provided, or not known'))
2023-05-22 21:25:56 - Error: HTTPSConnectionPool(host='api.telegram.org', port=443): Max retries exceeded with url: /bot6260404903:AAEU0Ax58ULUNvM9rBva_NR4cEIdTelM7OI/getUpdates?offset=337823247&timeout=20 (Caused by NewConnectionError('<urllib3.connection.HTTPSConnection object at 0x104bc1880>: Failed to establish a new connection: [Errno 8] nodename nor servname provided, or not known'))
2023-05-22 21:25:56 - Failed to send error message: HTTPSConnectionPool(host='api.telegram.org', port=443): Max retries exceeded with url: /bot6260404903:AAEU0Ax58ULUNvM9rBva_NR4cEIdTelM7OI/sendMessage?chat_id=455162494&text=%D0%9F%D1%80%D0%BE%D0%B8%D0%B7%D0%BE%D1%88%D0%BB%D0%B0+%D0%BE%D1%88%D0%B8%D0%B1%D0%BA%D0%B0%3A+HTTPSConnectionPool%28host%3D%27api.telegram.org%27%2C+port%3D443%29%3A+Max+retries+exceeded+with+url%3A+%2Fbot6260404903%3AAAEU0Ax58ULUNvM9rBva_NR4cEIdTelM7OI%2FgetUpdates%3Foffset%3D337823247%26timeout%3D20+%28Caused+by+NewConnectionError%28%27%3Curllib3.connection.HTTPSConnection+object+at+0x104bc1880%3E%3A+Failed+to+establish+a+new+connection%3A+%5BErrno+8%5D+nodename+nor+servname+provided%2C+or+not+known%27%29%29 (Caused by NewConnectionError('<urllib3.connection.HTTPSConnection object at 0x104bc1790>: Failed to establish a new connection: [Errno 8] nodename nor servname provided, or not known'))
2023-05-22 21:26:06 - Error: HTTPSConnectionPool(host='api.telegram.org', port=443): Max retries exceeded with url: /bot6260404903:AAEU0Ax58ULUNvM9rBva_NR4cEIdTelM7OI/getUpdates?offset=337823247&timeout=20 (Caused by NewConnectionError('<urllib3.connection.HTTPSConnection object at 0x104c439d0>: Failed to establish a new connection: [Errno 8] nodename nor servname provided, or not known'))
2023-05-22 21:26:06 - Failed to send error message: HTTPSConnectionPool(host='api.telegram.org', port=443): Max retries exceeded with url: /bot6260404903:AAEU0Ax58ULUNvM9rBva_NR4cEIdTelM7OI/sendMessage?chat_id=455162494&text=%D0%9F%D1%80%D0%BE%D0%B8%D0%B7%D0%BE%D1%88%D0%BB%D0%B0+%D0%BE%D1%88%D0%B8%D0%B1%D0%BA%D0%B0%3A+HTTPSConnectionPool%28host%3D%27api.telegram.org%27%2C+port%3D443%29%3A+Max+retries+exceeded+with+url%3A+%2Fbot6260404903%3AAAEU0Ax58ULUNvM9rBva_NR4cEIdTelM7OI%2FgetUpdates%3Foffset%3D337823247%26timeout%3D20+%28Caused+by+NewConnectionError%28%27%3Curllib3.connection.HTTPSConnection+object+at+0x104c439d0%3E%3A+Failed+to+establish+a+new+connection%3A+%5BErrno+8%5D+nodename+nor+servname+provided%2C+or+not+known%27%29%29 (Caused by NewConnectionError('<urllib3.connection.HTTPSConnection object at 0x104e31070>: Failed to establish a new connection: [Errno 8] nodename nor servname provided, or not known'))
2023-05-22 21:26:16 - Error: HTTPSConnectionPool(host='api.telegram.org', port=443): Max retries exceeded with url: /bot6260404903:AAEU0Ax58ULUNvM9rBva_NR4cEIdTelM7OI/getUpdates?offset=337823247&timeout=20 (Caused by NewConnectionError('<urllib3.connection.HTTPSConnection object at 0x104e31f70>: Failed to establish a new connection: [Errno 8] nodename nor servname provided, or not known'))
2023-05-22 21:26:16 - Failed to send error message: HTTPSConnectionPool(host='api.telegram.org', port=443): Max retries exceeded with url: /bot6260404903:AAEU0Ax58ULUNvM9rBva_NR4cEIdTelM7OI/sendMessage?chat_id=455162494&text=%D0%9F%D1%80%D0%BE%D0%B8%D0%B7%D0%BE%D1%88%D0%BB%D0%B0+%D0%BE%D1%88%D0%B8%D0%B1%D0%BA%D0%B0%3A+HTTPSConnectionPool%28host%3D%27api.telegram.org%27%2C+port%3D443%29%3A+Max+retries+exceeded+with+url%3A+%2Fbot6260404903%3AAAEU0Ax58ULUNvM9rBva_NR4cEIdTelM7OI%2FgetUpdates%3Foffset%3D337823247%26timeout%3D20+%28Caused+by+NewConnectionError%28%27%3Curllib3.connection.HTTPSConnection+object+at+0x104e31f70%3E%3A+Failed+to+establish+a+new+connection%3A+%5BErrno+8%5D+nodename+nor+servname+provided%2C+or+not+known%27%29%29 (Caused by NewConnectionError('<urllib3.connection.HTTPSConnection object at 0x104c43e50>: Failed to establish a new connection: [Errno 8] nodename nor servname provided, or not known'))
2023-05-22 21:26:26 - Error: HTTPSConnectionPool(host='api.telegram.org', port=443): Max retries exceeded with url: /bot6260404903:AAEU0Ax58ULUNvM9rBva_NR4cEIdTelM7OI/getUpdates?offset=337823247&timeout=20 (Caused by NewConnectionError('<urllib3.connection.HTTPSConnection object at 0x104bc1fd0>: Failed to establish a new connection: [Errno 8] nodename nor servname provided, or not known'))
2023-05-22 21:26:26 - Failed to send error message: HTTPSConnectionPool(host='api.telegram.org', port=443): Max retries exceeded with url: /bot6260404903:AAEU0Ax58ULUNvM9rBva_NR4cEIdTelM7OI/sendMessage?chat_id=455162494&text=%D0%9F%D1%80%D0%BE%D0%B8%D0%B7%D0%BE%D1%88%D0%BB%D0%B0+%D0%BE%D1%88%D0%B8%D0%B1%D0%BA%D0%B0%3A+HTTPSConnectionPool%28host%3D%27api.telegram.org%27%2C+port%3D443%29%3A+Max+retries+exceeded+with+url%3A+%2Fbot6260404903%3AAAEU0Ax58ULUNvM9rBva_NR4cEIdTelM7OI%2FgetUpdates%3Foffset%3D337823247%26timeout%3D20+%28Caused+by+NewConnectionError%28%27%3Curllib3.connection.HTTPSConnection+object+at+0x104bc1fd0%3E%3A+Failed+to+establish+a+new+connection%3A+%5BErrno+8%5D+nodename+nor+servname+provided%2C+or+not+known%27%29%29 (Caused by NewConnectionError('<urllib3.connection.HTTPSConnection object at 0x104bc1130>: Failed to establish a new connection: [Errno 8] nodename nor servname provided, or not known'))
2023-05-22 21:33:28 - Error: HTTPSConnectionPool(host='api.telegram.org', port=443): Max retries exceeded with url: /bot6260404903:AAEU0Ax58ULUNvM9rBva_NR4cEIdTelM7OI/getUpdates?offset=337823247&timeout=20 (Caused by NewConnectionError('<urllib3.connection.HTTPSConnection object at 0x104cabfd0>: Failed to establish a new connection: [Errno 8] nodename nor servname provided, or not known'))
2023-05-22 21:33:28 - Failed to send error message: HTTPSConnectionPool(host='api.telegram.org', port=443): Max retries exceeded with url: /bot6260404903:AAEU0Ax58ULUNvM9rBva_NR4cEIdTelM7OI/sendMessage?chat_id=455162494&text=%D0%9F%D1%80%D0%BE%D0%B8%D0%B7%D0%BE%D1%88%D0%BB%D0%B0+%D0%BE%D1%88%D0%B8%D0%B1%D0%BA%D0%B0%3A+HTTPSConnectionPool%28host%3D%27api.telegram.org%27%2C+port%3D443%29%3A+Max+retries+exceeded+with+url%3A+%2Fbot6260404903%3AAAEU0Ax58ULUNvM9rBva_NR4cEIdTelM7OI%2FgetUpdates%3Foffset%3D337823247%26timeout%3D20+%28Caused+by+NewConnectionError%28%27%3Curllib3.connection.HTTPSConnection+object+at+0x104cabfd0%3E%3A+Failed+to+establish+a+new+connection%3A+%5BErrno+8%5D+nodename+nor+servname+provided%2C+or+not+known%27%29%29 (Caused by NewConnectionError('<urllib3.connection.HTTPSConnection object at 0x104cb4d90>: Failed to establish a new connection: [Errno 8] nodename nor servname provided, or not known'))
2023-05-22 21:33:38 - Error: HTTPSConnectionPool(host='api.telegram.org', port=443): Max retries exceeded with url: /bot6260404903:AAEU0Ax58ULUNvM9rBva_NR4cEIdTelM7OI/getUpdates?offset=337823247&timeout=20 (Caused by NewConnectionError('<urllib3.connection.HTTPSConnection object at 0x104e3d220>: Failed to establish a new connection: [Errno 8] nodename nor servname provided, or not known'))
2023-05-22 21:33:38 - Failed to send error message: HTTPSConnectionPool(host='api.telegram.org', port=443): Max retries exceeded with url: /bot6260404903:AAEU0Ax58ULUNvM9rBva_NR4cEIdTelM7OI/sendMessage?chat_id=455162494&text=%D0%9F%D1%80%D0%BE%D0%B8%D0%B7%D0%BE%D1%88%D0%BB%D0%B0+%D0%BE%D1%88%D0%B8%D0%B1%D0%BA%D0%B0%3A+HTTPSConnectionPool%28host%3D%27api.telegram.org%27%2C+port%3D443%29%3A+Max+retries+exceeded+with+url%3A+%2Fbot6260404903%3AAAEU0Ax58ULUNvM9rBva_NR4cEIdTelM7OI%2FgetUpdates%3Foffset%3D337823247%26timeout%3D20+%28Caused+by+NewConnectionError%28%27%3Curllib3.connection.HTTPSConnection+object+at+0x104e3d220%3E%3A+Failed+to+establish+a+new+connection%3A+%5BErrno+8%5D+nodename+nor+servname+provided%2C+or+not+known%27%29%29 (Caused by NewConnectionError('<urllib3.connection.HTTPSConnection object at 0x104c4d910>: Failed to establish a new connection: [Errno 8] nodename nor servname provided, or not known'))
2023-05-22 21:33:48 - Error: HTTPSConnectionPool(host='api.telegram.org', port=443): Max retries exceeded with url: /bot6260404903:AAEU0Ax58ULUNvM9rBva_NR4cEIdTelM7OI/getUpdates?offset=337823247&timeout=20 (Caused by NewConnectionError('<urllib3.connection.HTTPSConnection object at 0x104bc1670>: Failed to establish a new connection: [Errno 8] nodename nor servname provided, or not known'))
2023-05-22 21:33:48 - Failed to send error message: HTTPSConnectionPool(host='api.telegram.org', port=443): Max retries exceeded with url: /bot6260404903:AAEU0Ax58ULUNvM9rBva_NR4cEIdTelM7OI/sendMessage?chat_id=455162494&text=%D0%9F%D1%80%D0%BE%D0%B8%D0%B7%D0%BE%D1%88%D0%BB%D0%B0+%D0%BE%D1%88%D0%B8%D0%B1%D0%BA%D0%B0%3A+HTTPSConnectionPool%28host%3D%27api.telegram.org%27%2C+port%3D443%29%3A+Max+retries+exceeded+with+url%3A+%2Fbot6260404903%3AAAEU0Ax58ULUNvM9rBva_NR4cEIdTelM7OI%2FgetUpdates%3Foffset%3D337823247%26timeout%3D20+%28Caused+by+NewConnectionError%28%27%3Curllib3.connection.HTTPSConnection+object+at+0x104bc1670%3E%3A+Failed+to+establish+a+new+connection%3A+%5BErrno+8%5D+nodename+nor+servname+provided%2C+or+not+known%27%29%29 (Caused by NewConnectionError('<urllib3.connection.HTTPSConnection object at 0x104bc1af0>: Failed to establish a new connection: [Errno 8] nodename nor servname provided, or not known'))
2023-05-22 21:33:58 - Error: HTTPSConnectionPool(host='api.telegram.org', port=443): Max retries exceeded with url: /bot6260404903:AAEU0Ax58ULUNvM9rBva_NR4cEIdTelM7OI/getUpdates?offset=337823247&timeout=20 (Caused by NewConnectionError('<urllib3.connection.HTTPSConnection object at 0x104bcecd0>: Failed to establish a new connection: [Errno 8] nodename nor servname provided, or not known'))
2023-05-22 21:33:58 - Failed to send error message: HTTPSConnectionPool(host='api.telegram.org', port=443): Max retries exceeded with url: /bot6260404903:AAEU0Ax58ULUNvM9rBva_NR4cEIdTelM7OI/sendMessage?chat_id=455162494&text=%D0%9F%D1%80%D0%BE%D0%B8%D0%B7%D0%BE%D1%88%D0%BB%D0%B0+%D0%BE%D1%88%D0%B8%D0%B1%D0%BA%D0%B0%3A+HTTPSConnectionPool%28host%3D%27api.telegram.org%27%2C+port%3D443%29%3A+Max+retries+exceeded+with+url%3A+%2Fbot6260404903%3AAAEU0Ax58ULUNvM9rBva_NR4cEIdTelM7OI%2FgetUpdates%3Foffset%3D337823247%26timeout%3D20+%28Caused+by+NewConnectionError%28%27%3Curllib3.connection.HTTPSConnection+object+at+0x104bcecd0%3E%3A+Failed+to+establish+a+new+connection%3A+%5BErrno+8%5D+nodename+nor+servname+provided%2C+or+not+known%27%29%29 (Caused by NewConnectionError('<urllib3.connection.HTTPSConnection object at 0x104e3d4f0>: Failed to establish a new connection: [Errno 8] nodename nor servname provided, or not known'))
2023-05-22 21:34:08 - Error: HTTPSConnectionPool(host='api.telegram.org', port=443): Max retries exceeded with url: /bot6260404903:AAEU0Ax58ULUNvM9rBva_NR4cEIdTelM7OI/getUpdates?offset=337823247&timeout=20 (Caused by NewConnectionError('<urllib3.connection.HTTPSConnection object at 0x104e43610>: Failed to establish a new connection: [Errno 8] nodename nor servname provided, or not known'))
2023-05-22 21:34:08 - Failed to send error message: HTTPSConnectionPool(host='api.telegram.org', port=443): Max retries exceeded with url: /bot6260404903:AAEU0Ax58ULUNvM9rBva_NR4cEIdTelM7OI/sendMessage?chat_id=455162494&text=%D0%9F%D1%80%D0%BE%D0%B8%D0%B7%D0%BE%D1%88%D0%BB%D0%B0+%D0%BE%D1%88%D0%B8%D0%B1%D0%BA%D0%B0%3A+HTTPSConnectionPool%28host%3D%27api.telegram.org%27%2C+port%3D443%29%3A+Max+retries+exceeded+with+url%3A+%2Fbot6260404903%3AAAEU0Ax58ULUNvM9rBva_NR4cEIdTelM7OI%2FgetUpdates%3Foffset%3D337823247%26timeout%3D20+%28Caused+by+NewConnectionError%28%27%3Curllib3.connection.HTTPSConnection+object+at+0x104e43610%3E%3A+Failed+to+establish+a+new+connection%3A+%5BErrno+8%5D+nodename+nor+servname+provided%2C+or+not+known%27%29%29 (Caused by NewConnectionError('<urllib3.connection.HTTPSConnection object at 0x104bce850>: Failed to establish a new connection: [Errno 8] nodename nor servname provided, or not known'))
2023-05-22 21:34:18 - Error: HTTPSConnectionPool(host='api.telegram.org', port=443): Max retries exceeded with url: /bot6260404903:AAEU0Ax58ULUNvM9rBva_NR4cEIdTelM7OI/getUpdates?offset=337823247&timeout=20 (Caused by NewConnectionError('<urllib3.connection.HTTPSConnection object at 0x104bc17c0>: Failed to establish a new connection: [Errno 8] nodename nor servname provided, or not known'))
2023-05-22 21:34:18 - Failed to send error message: HTTPSConnectionPool(host='api.telegram.org', port=443): Max retries exceeded with url: /bot6260404903:AAEU0Ax58ULUNvM9rBva_NR4cEIdTelM7OI/sendMessage?chat_id=455162494&text=%D0%9F%D1%80%D0%BE%D0%B8%D0%B7%D0%BE%D1%88%D0%BB%D0%B0+%D0%BE%D1%88%D0%B8%D0%B1%D0%BA%D0%B0%3A+HTTPSConnectionPool%28host%3D%27api.telegram.org%27%2C+port%3D443%29%3A+Max+retries+exceeded+with+url%3A+%2Fbot6260404903%3AAAEU0Ax58ULUNvM9rBva_NR4cEIdTelM7OI%2FgetUpdates%3Foffset%3D337823247%26timeout%3D20+%28Caused+by+NewConnectionError%28%27%3Curllib3.connection.HTTPSConnection+object+at+0x104bc17c0%3E%3A+Failed+to+establish+a+new+connection%3A+%5BErrno+8%5D+nodename+nor+servname+provided%2C+or+not+known%27%29%29 (Caused by NewConnectionError('<urllib3.connection.HTTPSConnection object at 0x104bc1520>: Failed to establish a new connection: [Errno 8] nodename nor servname provided, or not known'))
2023-05-22 21:34:28 - Error: HTTPSConnectionPool(host='api.telegram.org', port=443): Max retries exceeded with url: /bot6260404903:AAEU0Ax58ULUNvM9rBva_NR4cEIdTelM7OI/getUpdates?offset=337823247&timeout=20 (Caused by NewConnectionError('<urllib3.connection.HTTPSConnection object at 0x104cab130>: Failed to establish a new connection: [Errno 8] nodename nor servname provided, or not known'))
2023-05-22 21:34:28 - Failed to send error message: HTTPSConnectionPool(host='api.telegram.org', port=443): Max retries exceeded with url: /bot6260404903:AAEU0Ax58ULUNvM9rBva_NR4cEIdTelM7OI/sendMessage?chat_id=455162494&text=%D0%9F%D1%80%D0%BE%D0%B8%D0%B7%D0%BE%D1%88%D0%BB%D0%B0+%D0%BE%D1%88%D0%B8%D0%B1%D0%BA%D0%B0%3A+HTTPSConnectionPool%28host%3D%27api.telegram.org%27%2C+port%3D443%29%3A+Max+retries+exceeded+with+url%3A+%2Fbot6260404903%3AAAEU0Ax58ULUNvM9rBva_NR4cEIdTelM7OI%2FgetUpdates%3Foffset%3D337823247%26timeout%3D20+%28Caused+by+NewConnectionError%28%27%3Curllib3.connection.HTTPSConnection+object+at+0x104cab130%3E%3A+Failed+to+establish+a+new+connection%3A+%5BErrno+8%5D+nodename+nor+servname+provided%2C+or+not+known%27%29%29 (Caused by NewConnectionError('<urllib3.connection.HTTPSConnection object at 0x104e438e0>: Failed to establish a new connection: [Errno 8] nodename nor servname provided, or not known'))
2023-05-22 21:34:38 - Error: HTTPSConnectionPool(host='api.telegram.org', port=443): Max retries exceeded with url: /bot6260404903:AAEU0Ax58ULUNvM9rBva_NR4cEIdTelM7OI/getUpdates?offset=337823247&timeout=20 (Caused by NewConnectionError('<urllib3.connection.HTTPSConnection object at 0x104e4ba00>: Failed to establish a new connection: [Errno 8] nodename nor servname provided, or not known'))
2023-05-22 21:34:38 - Failed to send error message: HTTPSConnectionPool(host='api.telegram.org', port=443): Max retries exceeded with url: /bot6260404903:AAEU0Ax58ULUNvM9rBva_NR4cEIdTelM7OI/sendMessage?chat_id=455162494&text=%D0%9F%D1%80%D0%BE%D0%B8%D0%B7%D0%BE%D1%88%D0%BB%D0%B0+%D0%BE%D1%88%D0%B8%D0%B1%D0%BA%D0%B0%3A+HTTPSConnectionPool%28host%3D%27api.telegram.org%27%2C+port%3D443%29%3A+Max+retries+exceeded+with+url%3A+%2Fbot6260404903%3AAAEU0Ax58ULUNvM9rBva_NR4cEIdTelM7OI%2FgetUpdates%3Foffset%3D337823247%26timeout%3D20+%28Caused+by+NewConnectionError%28%27%3Curllib3.connection.HTTPSConnection+object+at+0x104e4ba00%3E%3A+Failed+to+establish+a+new+connection%3A+%5BErrno+8%5D+nodename+nor+servname+provided%2C+or+not+known%27%29%29 (Caused by NewConnectionError('<urllib3.connection.HTTPSConnection object at 0x104c4d940>: Failed to establish a new connection: [Errno 8] nodename nor servname provided, or not known'))
2023-05-22 21:36:20 - Error: HTTPSConnectionPool(host='api.telegram.org', port=443): Max retries exceeded with url: /bot6260404903:AAEU0Ax58ULUNvM9rBva_NR4cEIdTelM7OI/getUpdates?offset=337823247&timeout=20 (Caused by NewConnectionError('<urllib3.connection.HTTPSConnection object at 0x104c43c10>: Failed to establish a new connection: [Errno 8] nodename nor servname provided, or not known'))
2023-05-22 21:36:20 - Failed to send error message: HTTPSConnectionPool(host='api.telegram.org', port=443): Max retries exceeded with url: /bot6260404903:AAEU0Ax58ULUNvM9rBva_NR4cEIdTelM7OI/sendMessage?chat_id=455162494&text=%D0%9F%D1%80%D0%BE%D0%B8%D0%B7%D0%BE%D1%88%D0%BB%D0%B0+%D0%BE%D1%88%D0%B8%D0%B1%D0%BA%D0%B0%3A+HTTPSConnectionPool%28host%3D%27api.telegram.org%27%2C+port%3D443%29%3A+Max+retries+exceeded+with+url%3A+%2Fbot6260404903%3AAAEU0Ax58ULUNvM9rBva_NR4cEIdTelM7OI%2FgetUpdates%3Foffset%3D337823247%26timeout%3D20+%28Caused+by+NewConnectionError%28%27%3Curllib3.connection.HTTPSConnection+object+at+0x104c43c10%3E%3A+Failed+to+establish+a+new+connection%3A+%5BErrno+8%5D+nodename+nor+servname+provided%2C+or+not+known%27%29%29 (Caused by NewConnectionError('<urllib3.connection.HTTPSConnection object at 0x104c03460>: Failed to establish a new connection: [Errno 8] nodename nor servname provided, or not known'))
2023-05-22 21:37:52 - Error: HTTPSConnectionPool(host='api.telegram.org', port=443): Max retries exceeded with url: /bot6260404903:AAEU0Ax58ULUNvM9rBva_NR4cEIdTelM7OI/getUpdates?offset=337823247&timeout=20 (Caused by NewConnectionError('<urllib3.connection.HTTPSConnection object at 0x104bcea00>: Failed to establish a new connection: [Errno 8] nodename nor servname provided, or not known'))
2023-05-22 21:37:52 - Failed to send error message: HTTPSConnectionPool(host='api.telegram.org', port=443): Max retries exceeded with url: /bot6260404903:AAEU0Ax58ULUNvM9rBva_NR4cEIdTelM7OI/sendMessage?chat_id=455162494&text=%D0%9F%D1%80%D0%BE%D0%B8%D0%B7%D0%BE%D1%88%D0%BB%D0%B0+%D0%BE%D1%88%D0%B8%D0%B1%D0%BA%D0%B0%3A+HTTPSConnectionPool%28host%3D%27api.telegram.org%27%2C+port%3D443%29%3A+Max+retries+exceeded+with+url%3A+%2Fbot6260404903%3AAAEU0Ax58ULUNvM9rBva_NR4cEIdTelM7OI%2FgetUpdates%3Foffset%3D337823247%26timeout%3D20+%28Caused+by+NewConnectionError%28%27%3Curllib3.connection.HTTPSConnection+object+at+0x104bcea00%3E%3A+Failed+to+establish+a+new+connection%3A+%5BErrno+8%5D+nodename+nor+servname+provided%2C+or+not+known%27%29%29 (Caused by NewConnectionError('<urllib3.connection.HTTPSConnection object at 0x104e4bca0>: Failed to establish a new connection: [Errno 8] nodename nor servname provided, or not known'))
2023-05-22 21:39:30 - Error: HTTPSConnectionPool(host='api.telegram.org', port=443): Max retries exceeded with url: /bot6260404903:AAEU0Ax58ULUNvM9rBva_NR4cEIdTelM7OI/getUpdates?offset=337823247&timeout=20 (Caused by NewConnectionError('<urllib3.connection.HTTPSConnection object at 0x104e52df0>: Failed to establish a new connection: [Errno 8] nodename nor servname provided, or not known'))
2023-05-22 21:39:30 - Failed to send error message: HTTPSConnectionPool(host='api.telegram.org', port=443): Max retries exceeded with url: /bot6260404903:AAEU0Ax58ULUNvM9rBva_NR4cEIdTelM7OI/sendMessage?chat_id=455162494&text=%D0%9F%D1%80%D0%BE%D0%B8%D0%B7%D0%BE%D1%88%D0%BB%D0%B0+%D0%BE%D1%88%D0%B8%D0%B1%D0%BA%D0%B0%3A+HTTPSConnectionPool%28host%3D%27api.telegram.org%27%2C+port%3D443%29%3A+Max+retries+exceeded+with+url%3A+%2Fbot6260404903%3AAAEU0Ax58ULUNvM9rBva_NR4cEIdTelM7OI%2FgetUpdates%3Foffset%3D337823247%26timeout%3D20+%28Caused+by+NewConnectionError%28%27%3Curllib3.connection.HTTPSConnection+object+at+0x104e52df0%3E%3A+Failed+to+establish+a+new+connection%3A+%5BErrno+8%5D+nodename+nor+servname+provided%2C+or+not+known%27%29%29 (Caused by NewConnectionError('<urllib3.connection.HTTPSConnection object at 0x104bcec10>: Failed to establish a new connection: [Errno 8] nodename nor servname provided, or not known'))
2023-05-22 21:41:03 - Error: HTTPSConnectionPool(host='api.telegram.org', port=443): Max retries exceeded with url: /bot6260404903:AAEU0Ax58ULUNvM9rBva_NR4cEIdTelM7OI/getUpdates?offset=337823247&timeout=20 (Caused by NewConnectionError('<urllib3.connection.HTTPSConnection object at 0x104c439d0>: Failed to establish a new connection: [Errno 8] nodename nor servname provided, or not known'))
2023-05-22 21:41:03 - Failed to send error message: HTTPSConnectionPool(host='api.telegram.org', port=443): Max retries exceeded with url: /bot6260404903:AAEU0Ax58ULUNvM9rBva_NR4cEIdTelM7OI/sendMessage?chat_id=455162494&text=%D0%9F%D1%80%D0%BE%D0%B8%D0%B7%D0%BE%D1%88%D0%BB%D0%B0+%D0%BE%D1%88%D0%B8%D0%B1%D0%BA%D0%B0%3A+HTTPSConnectionPool%28host%3D%27api.telegram.org%27%2C+port%3D443%29%3A+Max+retries+exceeded+with+url%3A+%2Fbot6260404903%3AAAEU0Ax58ULUNvM9rBva_NR4cEIdTelM7OI%2FgetUpdates%3Foffset%3D337823247%26timeout%3D20+%28Caused+by+NewConnectionError%28%27%3Curllib3.connection.HTTPSConnection+object+at+0x104c439d0%3E%3A+Failed+to+establish+a+new+connection%3A+%5BErrno+8%5D+nodename+nor+servname+provided%2C+or+not+known%27%29%29 (Caused by NewConnectionError('<urllib3.connection.HTTPSConnection object at 0x104c43d30>: Failed to establish a new connection: [Errno 8] nodename nor servname provided, or not known'))
2023-05-22 21:42:16 - Error: HTTPSConnectionPool(host='api.telegram.org', port=443): Max retries exceeded with url: /bot6260404903:AAEU0Ax58ULUNvM9rBva_NR4cEIdTelM7OI/getUpdates?offset=337823247&timeout=20 (Caused by NewConnectionError('<urllib3.connection.HTTPSConnection object at 0x104cab700>: Failed to establish a new connection: [Errno 8] nodename nor servname provided, or not known'))
2023-05-22 21:42:16 - Failed to send error message: HTTPSConnectionPool(host='api.telegram.org', port=443): Max retries exceeded with url: /bot6260404903:AAEU0Ax58ULUNvM9rBva_NR4cEIdTelM7OI/sendMessage?chat_id=455162494&text=%D0%9F%D1%80%D0%BE%D0%B8%D0%B7%D0%BE%D1%88%D0%BB%D0%B0+%D0%BE%D1%88%D0%B8%D0%B1%D0%BA%D0%B0%3A+HTTPSConnectionPool%28host%3D%27api.telegram.org%27%2C+port%3D443%29%3A+Max+retries+exceeded+with+url%3A+%2Fbot6260404903%3AAAEU0Ax58ULUNvM9rBva_NR4cEIdTelM7OI%2FgetUpdates%3Foffset%3D337823247%26timeout%3D20+%28Caused+by+NewConnectionError%28%27%3Curllib3.connection.HTTPSConnection+object+at+0x104cab700%3E%3A+Failed+to+establish+a+new+connection%3A+%5BErrno+8%5D+nodename+nor+servname+provided%2C+or+not+known%27%29%29 (Caused by NewConnectionError('<urllib3.connection.HTTPSConnection object at 0x104e5a0d0>: Failed to establish a new connection: [Errno 8] nodename nor servname provided, or not known'))
2023-05-22 21:42:42 - Error: HTTPSConnectionPool(host='api.telegram.org', port=443): Max retries exceeded with url: /bot6260404903:AAEU0Ax58ULUNvM9rBva_NR4cEIdTelM7OI/getUpdates?offset=337823247&timeout=20 (Caused by NewConnectionError('<urllib3.connection.HTTPSConnection object at 0x104e61220>: Failed to establish a new connection: [Errno 8] nodename nor servname provided, or not known'))
2023-05-22 21:42:42 - Failed to send error message: HTTPSConnectionPool(host='api.telegram.org', port=443): Max retries exceeded with url: /bot6260404903:AAEU0Ax58ULUNvM9rBva_NR4cEIdTelM7OI/sendMessage?chat_id=455162494&text=%D0%9F%D1%80%D0%BE%D0%B8%D0%B7%D0%BE%D1%88%D0%BB%D0%B0+%D0%BE%D1%88%D0%B8%D0%B1%D0%BA%D0%B0%3A+HTTPSConnectionPool%28host%3D%27api.telegram.org%27%2C+port%3D443%29%3A+Max+retries+exceeded+with+url%3A+%2Fbot6260404903%3AAAEU0Ax58ULUNvM9rBva_NR4cEIdTelM7OI%2FgetUpdates%3Foffset%3D337823247%26timeout%3D20+%28Caused+by+NewConnectionError%28%27%3Curllib3.connection.HTTPSConnection+object+at+0x104e61220%3E%3A+Failed+to+establish+a+new+connection%3A+%5BErrno+8%5D+nodename+nor+servname+provided%2C+or+not+known%27%29%29 (Caused by NewConnectionError('<urllib3.connection.HTTPSConnection object at 0x104c4d910>: Failed to establish a new connection: [Errno 8] nodename nor servname provided, or not known'))
2023-05-22 21:43:44 - Error: HTTPSConnectionPool(host='api.telegram.org', port=443): Max retries exceeded with url: /bot6260404903:AAEU0Ax58ULUNvM9rBva_NR4cEIdTelM7OI/getUpdates?offset=337823247&timeout=20 (Caused by NewConnectionError('<urllib3.connection.HTTPSConnection object at 0x104c43820>: Failed to establish a new connection: [Errno 8] nodename nor servname provided, or not known'))
2023-05-22 21:43:44 - Failed to send error message: HTTPSConnectionPool(host='api.telegram.org', port=443): Max retries exceeded with url: /bot6260404903:AAEU0Ax58ULUNvM9rBva_NR4cEIdTelM7OI/sendMessage?chat_id=455162494&text=%D0%9F%D1%80%D0%BE%D0%B8%D0%B7%D0%BE%D1%88%D0%BB%D0%B0+%D0%BE%D1%88%D0%B8%D0%B1%D0%BA%D0%B0%3A+HTTPSConnectionPool%28host%3D%27api.telegram.org%27%2C+port%3D443%29%3A+Max+retries+exceeded+with+url%3A+%2Fbot6260404903%3AAAEU0Ax58ULUNvM9rBva_NR4cEIdTelM7OI%2FgetUpdates%3Foffset%3D337823247%26timeout%3D20+%28Caused+by+NewConnectionError%28%27%3Curllib3.connection.HTTPSConnection+object+at+0x104c43820%3E%3A+Failed+to+establish+a+new+connection%3A+%5BErrno+8%5D+nodename+nor+servname+provided%2C+or+not+known%27%29%29 (Caused by NewConnectionError('<urllib3.connection.HTTPSConnection object at 0x104e343d0>: Failed to establish a new connection: [Errno 8] nodename nor servname provided, or not known'))
2023-05-22 21:44:13 - Error: HTTPSConnectionPool(host='api.telegram.org', port=443): Max retries exceeded with url: /bot6260404903:AAEU0Ax58ULUNvM9rBva_NR4cEIdTelM7OI/getUpdates?offset=337823247&timeout=20 (Caused by NewConnectionError('<urllib3.connection.HTTPSConnection object at 0x104bc1760>: Failed to establish a new connection: [Errno 8] nodename nor servname provided, or not known'))
2023-05-22 21:44:14 - Failed to send error message: HTTPSConnectionPool(host='api.telegram.org', port=443): Max retries exceeded with url: /bot6260404903:AAEU0Ax58ULUNvM9rBva_NR4cEIdTelM7OI/sendMessage?chat_id=455162494&text=%D0%9F%D1%80%D0%BE%D0%B8%D0%B7%D0%BE%D1%88%D0%BB%D0%B0+%D0%BE%D1%88%D0%B8%D0%B1%D0%BA%D0%B0%3A+HTTPSConnectionPool%28host%3D%27api.telegram.org%27%2C+port%3D443%29%3A+Max+retries+exceeded+with+url%3A+%2Fbot6260404903%3AAAEU0Ax58ULUNvM9rBva_NR4cEIdTelM7OI%2FgetUpdates%3Foffset%3D337823247%26timeout%3D20+%28Caused+by+NewConnectionError%28%27%3Curllib3.connection.HTTPSConnection+object+at+0x104bc1760%3E%3A+Failed+to+establish+a+new+connection%3A+%5BErrno+8%5D+nodename+nor+servname+provided%2C+or+not+known%27%29%29 (Caused by NewConnectionError('<urllib3.connection.HTTPSConnection object at 0x104e614c0>: Failed to establish a new connection: [Errno 8] nodename nor servname provided, or not known'))
2023-05-22 21:45:05 - Error: HTTPSConnectionPool(host='api.telegram.org', port=443): Max retries exceeded with url: /bot6260404903:AAEU0Ax58ULUNvM9rBva_NR4cEIdTelM7OI/getUpdates?offset=337823247&timeout=20 (Caused by NewConnectionError('<urllib3.connection.HTTPSConnection object at 0x104e68610>: Failed to establish a new connection: [Errno 8] nodename nor servname provided, or not known'))
2023-05-22 21:45:06 - Failed to send error message: HTTPSConnectionPool(host='api.telegram.org', port=443): Max retries exceeded with url: /bot6260404903:AAEU0Ax58ULUNvM9rBva_NR4cEIdTelM7OI/sendMessage?chat_id=455162494&text=%D0%9F%D1%80%D0%BE%D0%B8%D0%B7%D0%BE%D1%88%D0%BB%D0%B0+%D0%BE%D1%88%D0%B8%D0%B1%D0%BA%D0%B0%3A+HTTPSConnectionPool%28host%3D%27api.telegram.org%27%2C+port%3D443%29%3A+Max+retries+exceeded+with+url%3A+%2Fbot6260404903%3AAAEU0Ax58ULUNvM9rBva_NR4cEIdTelM7OI%2FgetUpdates%3Foffset%3D337823247%26timeout%3D20+%28Caused+by+NewConnectionError%28%27%3Curllib3.connection.HTTPSConnection+object+at+0x104e68610%3E%3A+Failed+to+establish+a+new+connection%3A+%5BErrno+8%5D+nodename+nor+servname+provided%2C+or+not+known%27%29%29 (Caused by NewConnectionError('<urllib3.connection.HTTPSConnection object at 0x104bc1970>: Failed to establish a new connection: [Errno 8] nodename nor servname provided, or not known'))
2023-05-22 21:45:22 - Error: HTTPSConnectionPool(host='api.telegram.org', port=443): Max retries exceeded with url: /bot6260404903:AAEU0Ax58ULUNvM9rBva_NR4cEIdTelM7OI/getUpdates?offset=337823247&timeout=20 (Caused by NewConnectionError('<urllib3.connection.HTTPSConnection object at 0x104b202e0>: Failed to establish a new connection: [Errno 8] nodename nor servname provided, or not known'))
2023-05-22 21:45:22 - Failed to send error message: HTTPSConnectionPool(host='api.telegram.org', port=443): Max retries exceeded with url: /bot6260404903:AAEU0Ax58ULUNvM9rBva_NR4cEIdTelM7OI/sendMessage?chat_id=455162494&text=%D0%9F%D1%80%D0%BE%D0%B8%D0%B7%D0%BE%D1%88%D0%BB%D0%B0+%D0%BE%D1%88%D0%B8%D0%B1%D0%BA%D0%B0%3A+HTTPSConnectionPool%28host%3D%27api.telegram.org%27%2C+port%3D443%29%3A+Max+retries+exceeded+with+url%3A+%2Fbot6260404903%3AAAEU0Ax58ULUNvM9rBva_NR4cEIdTelM7OI%2FgetUpdates%3Foffset%3D337823247%26timeout%3D20+%28Caused+by+NewConnectionError%28%27%3Curllib3.connection.HTTPSConnection+object+at+0x104b202e0%3E%3A+Failed+to+establish+a+new+connection%3A+%5BErrno+8%5D+nodename+nor+servname+provided%2C+or+not+known%27%29%29 (Caused by NewConnectionError('<urllib3.connection.HTTPSConnection object at 0x104e341c0>: Failed to establish a new connection: [Errno 8] nodename nor servname provided, or not known'))
2023-05-22 21:45:32 - Error: HTTPSConnectionPool(host='api.telegram.org', port=443): Max retries exceeded with url: /bot6260404903:AAEU0Ax58ULUNvM9rBva_NR4cEIdTelM7OI/getUpdates?offset=337823247&timeout=20 (Caused by NewConnectionError('<urllib3.connection.HTTPSConnection object at 0x104cabe50>: Failed to establish a new connection: [Errno 8] nodename nor servname provided, or not known'))
2023-05-22 21:45:32 - Failed to send error message: HTTPSConnectionPool(host='api.telegram.org', port=443): Max retries exceeded with url: /bot6260404903:AAEU0Ax58ULUNvM9rBva_NR4cEIdTelM7OI/sendMessage?chat_id=455162494&text=%D0%9F%D1%80%D0%BE%D0%B8%D0%B7%D0%BE%D1%88%D0%BB%D0%B0+%D0%BE%D1%88%D0%B8%D0%B1%D0%BA%D0%B0%3A+HTTPSConnectionPool%28host%3D%27api.telegram.org%27%2C+port%3D443%29%3A+Max+retries+exceeded+with+url%3A+%2Fbot6260404903%3AAAEU0Ax58ULUNvM9rBva_NR4cEIdTelM7OI%2FgetUpdates%3Foffset%3D337823247%26timeout%3D20+%28Caused+by+NewConnectionError%28%27%3Curllib3.connection.HTTPSConnection+object+at+0x104cabe50%3E%3A+Failed+to+establish+a+new+connection%3A+%5BErrno+8%5D+nodename+nor+servname+provided%2C+or+not+known%27%29%29 (Caused by NewConnectionError('<urllib3.connection.HTTPSConnection object at 0x104e688b0>: Failed to establish a new connection: [Errno 8] nodename nor servname provided, or not known'))
2023-05-22 21:46:04 - Error: HTTPSConnectionPool(host='api.telegram.org', port=443): Max retries exceeded with url: /bot6260404903:AAEU0Ax58ULUNvM9rBva_NR4cEIdTelM7OI/getUpdates?offset=337823247&timeout=20 (Caused by NewConnectionError('<urllib3.connection.HTTPSConnection object at 0x104e72a00>: Failed to establish a new connection: [Errno 8] nodename nor servname provided, or not known'))
2023-05-22 21:46:04 - Failed to send error message: HTTPSConnectionPool(host='api.telegram.org', port=443): Max retries exceeded with url: /bot6260404903:AAEU0Ax58ULUNvM9rBva_NR4cEIdTelM7OI/sendMessage?chat_id=455162494&text=%D0%9F%D1%80%D0%BE%D0%B8%D0%B7%D0%BE%D1%88%D0%BB%D0%B0+%D0%BE%D1%88%D0%B8%D0%B1%D0%BA%D0%B0%3A+HTTPSConnectionPool%28host%3D%27api.telegram.org%27%2C+port%3D443%29%3A+Max+retries+exceeded+with+url%3A+%2Fbot6260404903%3AAAEU0Ax58ULUNvM9rBva_NR4cEIdTelM7OI%2FgetUpdates%3Foffset%3D337823247%26timeout%3D20+%28Caused+by+NewConnectionError%28%27%3Curllib3.connection.HTTPSConnection+object+at+0x104e72a00%3E%3A+Failed+to+establish+a+new+connection%3A+%5BErrno+8%5D+nodename+nor+servname+provided%2C+or+not+known%27%29%29 (Caused by NewConnectionError('<urllib3.connection.HTTPSConnection object at 0x104c4d880>: Failed to establish a new connection: [Errno 8] nodename nor servname provided, or not known'))
2023-05-22 21:46:14 - Error: HTTPSConnectionPool(host='api.telegram.org', port=443): Max retries exceeded with url: /bot6260404903:AAEU0Ax58ULUNvM9rBva_NR4cEIdTelM7OI/getUpdates?offset=337823247&timeout=20 (Caused by NewConnectionError('<urllib3.connection.HTTPSConnection object at 0x104bce6a0>: Failed to establish a new connection: [Errno 8] nodename nor servname provided, or not known'))
2023-05-22 21:46:14 - Failed to send error message: HTTPSConnectionPool(host='api.telegram.org', port=443): Max retries exceeded with url: /bot6260404903:AAEU0Ax58ULUNvM9rBva_NR4cEIdTelM7OI/sendMessage?chat_id=455162494&text=%D0%9F%D1%80%D0%BE%D0%B8%D0%B7%D0%BE%D1%88%D0%BB%D0%B0+%D0%BE%D1%88%D0%B8%D0%B1%D0%BA%D0%B0%3A+HTTPSConnectionPool%28host%3D%27api.telegram.org%27%2C+port%3D443%29%3A+Max+retries+exceeded+with+url%3A+%2Fbot6260404903%3AAAEU0Ax58ULUNvM9rBva_NR4cEIdTelM7OI%2FgetUpdates%3Foffset%3D337823247%26timeout%3D20+%28Caused+by+NewConnectionError%28%27%3Curllib3.connection.HTTPSConnection+object+at+0x104bce6a0%3E%3A+Failed+to+establish+a+new+connection%3A+%5BErrno+8%5D+nodename+nor+servname+provided%2C+or+not+known%27%29%29 (Caused by NewConnectionError('<urllib3.connection.HTTPSConnection object at 0x104bce9a0>: Failed to establish a new connection: [Errno 8] nodename nor servname provided, or not known'))
2023-05-22 21:46:28 - Error: HTTPSConnectionPool(host='api.telegram.org', port=443): Max retries exceeded with url: /bot6260404903:AAEU0Ax58ULUNvM9rBva_NR4cEIdTelM7OI/getUpdates?offset=337823247&timeout=20 (Caused by NewConnectionError('<urllib3.connection.HTTPSConnection object at 0x104bc1a90>: Failed to establish a new connection: [Errno 8] nodename nor servname provided, or not known'))
2023-05-22 21:46:28 - Failed to send error message: HTTPSConnectionPool(host='api.telegram.org', port=443): Max retries exceeded with url: /bot6260404903:AAEU0Ax58ULUNvM9rBva_NR4cEIdTelM7OI/sendMessage?chat_id=455162494&text=%D0%9F%D1%80%D0%BE%D0%B8%D0%B7%D0%BE%D1%88%D0%BB%D0%B0+%D0%BE%D1%88%D0%B8%D0%B1%D0%BA%D0%B0%3A+HTTPSConnectionPool%28host%3D%27api.telegram.org%27%2C+port%3D443%29%3A+Max+retries+exceeded+with+url%3A+%2Fbot6260404903%3AAAEU0Ax58ULUNvM9rBva_NR4cEIdTelM7OI%2FgetUpdates%3Foffset%3D337823247%26timeout%3D20+%28Caused+by+NewConnectionError%28%27%3Curllib3.connection.HTTPSConnection+object+at+0x104bc1a90%3E%3A+Failed+to+establish+a+new+connection%3A+%5BErrno+8%5D+nodename+nor+servname+provided%2C+or+not+known%27%29%29 (Caused by NewConnectionError('<urllib3.connection.HTTPSConnection object at 0x104e72ca0>: Failed to establish a new connection: [Errno 8] nodename nor servname provided, or not known'))
2023-05-22 21:46:38 - Error: HTTPSConnectionPool(host='api.telegram.org', port=443): Max retries exceeded with url: /bot6260404903:AAEU0Ax58ULUNvM9rBva_NR4cEIdTelM7OI/getUpdates?offset=337823247&timeout=20 (Caused by NewConnectionError('<urllib3.connection.HTTPSConnection object at 0x104e78e20>: Failed to establish a new connection: [Errno 8] nodename nor servname provided, or not known'))
2023-05-22 21:46:38 - Failed to send error message: HTTPSConnectionPool(host='api.telegram.org', port=443): Max retries exceeded with url: /bot6260404903:AAEU0Ax58ULUNvM9rBva_NR4cEIdTelM7OI/sendMessage?chat_id=455162494&text=%D0%9F%D1%80%D0%BE%D0%B8%D0%B7%D0%BE%D1%88%D0%BB%D0%B0+%D0%BE%D1%88%D0%B8%D0%B1%D0%BA%D0%B0%3A+HTTPSConnectionPool%28host%3D%27api.telegram.org%27%2C+port%3D443%29%3A+Max+retries+exceeded+with+url%3A+%2Fbot6260404903%3AAAEU0Ax58ULUNvM9rBva_NR4cEIdTelM7OI%2FgetUpdates%3Foffset%3D337823247%26timeout%3D20+%28Caused+by+NewConnectionError%28%27%3Curllib3.connection.HTTPSConnection+object+at+0x104e78e20%3E%3A+Failed+to+establish+a+new+connection%3A+%5BErrno+8%5D+nodename+nor+servname+provided%2C+or+not+known%27%29%29 (Caused by NewConnectionError('<urllib3.connection.HTTPSConnection object at 0x104c03dc0>: Failed to establish a new connection: [Errno 8] nodename nor servname provided, or not known'))
2023-05-22 21:47:00 - Error: HTTPSConnectionPool(host='api.telegram.org', port=443): Max retries exceeded with url: /bot6260404903:AAEU0Ax58ULUNvM9rBva_NR4cEIdTelM7OI/getUpdates?offset=337823247&timeout=20 (Caused by NewConnectionError('<urllib3.connection.HTTPSConnection object at 0x104e34310>: Failed to establish a new connection: [Errno 8] nodename nor servname provided, or not known'))
2023-05-22 21:47:00 - Failed to send error message: HTTPSConnectionPool(host='api.telegram.org', port=443): Max retries exceeded with url: /bot6260404903:AAEU0Ax58ULUNvM9rBva_NR4cEIdTelM7OI/sendMessage?chat_id=455162494&text=%D0%9F%D1%80%D0%BE%D0%B8%D0%B7%D0%BE%D1%88%D0%BB%D0%B0+%D0%BE%D1%88%D0%B8%D0%B1%D0%BA%D0%B0%3A+HTTPSConnectionPool%28host%3D%27api.telegram.org%27%2C+port%3D443%29%3A+Max+retries+exceeded+with+url%3A+%2Fbot6260404903%3AAAEU0Ax58ULUNvM9rBva_NR4cEIdTelM7OI%2FgetUpdates%3Foffset%3D337823247%26timeout%3D20+%28Caused+by+NewConnectionError%28%27%3Curllib3.connection.HTTPSConnection+object+at+0x104e34310%3E%3A+Failed+to+establish+a+new+connection%3A+%5BErrno+8%5D+nodename+nor+servname+provided%2C+or+not+known%27%29%29 (Caused by NewConnectionError('<urllib3.connection.HTTPSConnection object at 0x104e342e0>: Failed to establish a new connection: [Errno 8] nodename nor servname provided, or not known'))
2023-05-22 21:47:28 - Error: HTTPSConnectionPool(host='api.telegram.org', port=443): Max retries exceeded with url: /bot6260404903:AAEU0Ax58ULUNvM9rBva_NR4cEIdTelM7OI/getUpdates?offset=337823247&timeout=20 (Caused by NewConnectionError('<urllib3.connection.HTTPSConnection object at 0x104cab9a0>: Failed to establish a new connection: [Errno 8] nodename nor servname provided, or not known'))
2023-05-22 21:47:28 - Failed to send error message: HTTPSConnectionPool(host='api.telegram.org', port=443): Max retries exceeded with url: /bot6260404903:AAEU0Ax58ULUNvM9rBva_NR4cEIdTelM7OI/sendMessage?chat_id=455162494&text=%D0%9F%D1%80%D0%BE%D0%B8%D0%B7%D0%BE%D1%88%D0%BB%D0%B0+%D0%BE%D1%88%D0%B8%D0%B1%D0%BA%D0%B0%3A+HTTPSConnectionPool%28host%3D%27api.telegram.org%27%2C+port%3D443%29%3A+Max+retries+exceeded+with+url%3A+%2Fbot6260404903%3AAAEU0Ax58ULUNvM9rBva_NR4cEIdTelM7OI%2FgetUpdates%3Foffset%3D337823247%26timeout%3D20+%28Caused+by+NewConnectionError%28%27%3Curllib3.connection.HTTPSConnection+object+at+0x104cab9a0%3E%3A+Failed+to+establish+a+new+connection%3A+%5BErrno+8%5D+nodename+nor+servname+provided%2C+or+not+known%27%29%29 (Caused by NewConnectionError('<urllib3.connection.HTTPSConnection object at 0x104e81100>: Failed to establish a new connection: [Errno 8] nodename nor servname provided, or not known'))
2023-05-22 21:47:59 - Error: HTTPSConnectionPool(host='api.telegram.org', port=443): Max retries exceeded with url: /bot6260404903:AAEU0Ax58ULUNvM9rBva_NR4cEIdTelM7OI/getUpdates?offset=337823247&timeout=20 (Caused by NewConnectionError('<urllib3.connection.HTTPSConnection object at 0x104e86250>: Failed to establish a new connection: [Errno 8] nodename nor servname provided, or not known'))
2023-05-22 21:47:59 - Failed to send error message: HTTPSConnectionPool(host='api.telegram.org', port=443): Max retries exceeded with url: /bot6260404903:AAEU0Ax58ULUNvM9rBva_NR4cEIdTelM7OI/sendMessage?chat_id=455162494&text=%D0%9F%D1%80%D0%BE%D0%B8%D0%B7%D0%BE%D1%88%D0%BB%D0%B0+%D0%BE%D1%88%D0%B8%D0%B1%D0%BA%D0%B0%3A+HTTPSConnectionPool%28host%3D%27api.telegram.org%27%2C+port%3D443%29%3A+Max+retries+exceeded+with+url%3A+%2Fbot6260404903%3AAAEU0Ax58ULUNvM9rBva_NR4cEIdTelM7OI%2FgetUpdates%3Foffset%3D337823247%26timeout%3D20+%28Caused+by+NewConnectionError%28%27%3Curllib3.connection.HTTPSConnection+object+at+0x104e86250%3E%3A+Failed+to+establish+a+new+connection%3A+%5BErrno+8%5D+nodename+nor+servname+provided%2C+or+not+known%27%29%29 (Caused by NewConnectionError('<urllib3.connection.HTTPSConnection object at 0x104e784c0>: Failed to establish a new connection: [Errno 8] nodename nor servname provided, or not known'))
2023-05-22 21:48:09 - Error: HTTPSConnectionPool(host='api.telegram.org', port=443): Max retries exceeded with url: /bot6260404903:AAEU0Ax58ULUNvM9rBva_NR4cEIdTelM7OI/getUpdates?offset=337823247&timeout=20 (Caused by NewConnectionError('<urllib3.connection.HTTPSConnection object at 0x104e72eb0>: Failed to establish a new connection: [Errno 8] nodename nor servname provided, or not known'))
2023-05-22 21:48:09 - Failed to send error message: HTTPSConnectionPool(host='api.telegram.org', port=443): Max retries exceeded with url: /bot6260404903:AAEU0Ax58ULUNvM9rBva_NR4cEIdTelM7OI/sendMessage?chat_id=455162494&text=%D0%9F%D1%80%D0%BE%D0%B8%D0%B7%D0%BE%D1%88%D0%BB%D0%B0+%D0%BE%D1%88%D0%B8%D0%B1%D0%BA%D0%B0%3A+HTTPSConnectionPool%28host%3D%27api.telegram.org%27%2C+port%3D443%29%3A+Max+retries+exceeded+with+url%3A+%2Fbot6260404903%3AAAEU0Ax58ULUNvM9rBva_NR4cEIdTelM7OI%2FgetUpdates%3Foffset%3D337823247%26timeout%3D20+%28Caused+by+NewConnectionError%28%27%3Curllib3.connection.HTTPSConnection+object+at+0x104e72eb0%3E%3A+Failed+to+establish+a+new+connection%3A+%5BErrno+8%5D+nodename+nor+servname+provided%2C+or+not+known%27%29%29 (Caused by NewConnectionError('<urllib3.connection.HTTPSConnection object at 0x104e72040>: Failed to establish a new connection: [Errno 8] nodename nor servname provided, or not known'))
2023-05-22 21:49:17 - Error: HTTPSConnectionPool(host='api.telegram.org', port=443): Max retries exceeded with url: /bot6260404903:AAEU0Ax58ULUNvM9rBva_NR4cEIdTelM7OI/getUpdates?offset=337823247&timeout=20 (Caused by NewConnectionError('<urllib3.connection.HTTPSConnection object at 0x104e68850>: Failed to establish a new connection: [Errno 8] nodename nor servname provided, or not known'))
2023-05-22 21:49:17 - Failed to send error message: HTTPSConnectionPool(host='api.telegram.org', port=443): Max retries exceeded with url: /bot6260404903:AAEU0Ax58ULUNvM9rBva_NR4cEIdTelM7OI/sendMessage?chat_id=455162494&text=%D0%9F%D1%80%D0%BE%D0%B8%D0%B7%D0%BE%D1%88%D0%BB%D0%B0+%D0%BE%D1%88%D0%B8%D0%B1%D0%BA%D0%B0%3A+HTTPSConnectionPool%28host%3D%27api.telegram.org%27%2C+port%3D443%29%3A+Max+retries+exceeded+with+url%3A+%2Fbot6260404903%3AAAEU0Ax58ULUNvM9rBva_NR4cEIdTelM7OI%2FgetUpdates%3Foffset%3D337823247%26timeout%3D20+%28Caused+by+NewConnectionError%28%27%3Curllib3.connection.HTTPSConnection+object+at+0x104e68850%3E%3A+Failed+to+establish+a+new+connection%3A+%5BErrno+8%5D+nodename+nor+servname+provided%2C+or+not+known%27%29%29 (Caused by NewConnectionError('<urllib3.connection.HTTPSConnection object at 0x104e68250>: Failed to establish a new connection: [Errno 8] nodename nor servname provided, or not known'))
2023-05-22 21:49:39 - Error: HTTPSConnectionPool(host='api.telegram.org', port=443): Max retries exceeded with url: /bot6260404903:AAEU0Ax58ULUNvM9rBva_NR4cEIdTelM7OI/getUpdates?offset=337823247&timeout=20 (Caused by NewConnectionError('<urllib3.connection.HTTPSConnection object at 0x104e61460>: Failed to establish a new connection: [Errno 8] nodename nor servname provided, or not known'))
2023-05-22 21:49:39 - Failed to send error message: HTTPSConnectionPool(host='api.telegram.org', port=443): Max retries exceeded with url: /bot6260404903:AAEU0Ax58ULUNvM9rBva_NR4cEIdTelM7OI/sendMessage?chat_id=455162494&text=%D0%9F%D1%80%D0%BE%D0%B8%D0%B7%D0%BE%D1%88%D0%BB%D0%B0+%D0%BE%D1%88%D0%B8%D0%B1%D0%BA%D0%B0%3A+HTTPSConnectionPool%28host%3D%27api.telegram.org%27%2C+port%3D443%29%3A+Max+retries+exceeded+with+url%3A+%2Fbot6260404903%3AAAEU0Ax58ULUNvM9rBva_NR4cEIdTelM7OI%2FgetUpdates%3Foffset%3D337823247%26timeout%3D20+%28Caused+by+NewConnectionError%28%27%3Curllib3.connection.HTTPSConnection+object+at+0x104e61460%3E%3A+Failed+to+establish+a+new+connection%3A+%5BErrno+8%5D+nodename+nor+servname+provided%2C+or+not+known%27%29%29 (Caused by NewConnectionError('<urllib3.connection.HTTPSConnection object at 0x104e72820>: Failed to establish a new connection: [Errno 8] nodename nor servname provided, or not known'))
2023-05-22 21:49:58 - Error: HTTPSConnectionPool(host='api.telegram.org', port=443): Max retries exceeded with url: /bot6260404903:AAEU0Ax58ULUNvM9rBva_NR4cEIdTelM7OI/getUpdates?offset=337823247&timeout=20 (Caused by NewConnectionError('<urllib3.connection.HTTPSConnection object at 0x104e78a90>: Failed to establish a new connection: [Errno 8] nodename nor servname provided, or not known'))
2023-05-22 21:49:58 - Failed to send error message: HTTPSConnectionPool(host='api.telegram.org', port=443): Max retries exceeded with url: /bot6260404903:AAEU0Ax58ULUNvM9rBva_NR4cEIdTelM7OI/sendMessage?chat_id=455162494&text=%D0%9F%D1%80%D0%BE%D0%B8%D0%B7%D0%BE%D1%88%D0%BB%D0%B0+%D0%BE%D1%88%D0%B8%D0%B1%D0%BA%D0%B0%3A+HTTPSConnectionPool%28host%3D%27api.telegram.org%27%2C+port%3D443%29%3A+Max+retries+exceeded+with+url%3A+%2Fbot6260404903%3AAAEU0Ax58ULUNvM9rBva_NR4cEIdTelM7OI%2FgetUpdates%3Foffset%3D337823247%26timeout%3D20+%28Caused+by+NewConnectionError%28%27%3Curllib3.connection.HTTPSConnection+object+at+0x104e78a90%3E%3A+Failed+to+establish+a+new+connection%3A+%5BErrno+8%5D+nodename+nor+servname+provided%2C+or+not+known%27%29%29 (Caused by NewConnectionError('<urllib3.connection.HTTPSConnection object at 0x104e78dc0>: Failed to establish a new connection: [Errno 8] nodename nor servname provided, or not known'))
2023-05-22 21:50:41 - Error: HTTPSConnectionPool(host='api.telegram.org', port=443): Max retries exceeded with url: /bot6260404903:AAEU0Ax58ULUNvM9rBva_NR4cEIdTelM7OI/getUpdates?offset=337823247&timeout=20 (Caused by NewConnectionError('<urllib3.connection.HTTPSConnection object at 0x104e68c70>: Failed to establish a new connection: [Errno 8] nodename nor servname provided, or not known'))
2023-05-22 21:50:41 - Failed to send error message: HTTPSConnectionPool(host='api.telegram.org', port=443): Max retries exceeded with url: /bot6260404903:AAEU0Ax58ULUNvM9rBva_NR4cEIdTelM7OI/sendMessage?chat_id=455162494&text=%D0%9F%D1%80%D0%BE%D0%B8%D0%B7%D0%BE%D1%88%D0%BB%D0%B0+%D0%BE%D1%88%D0%B8%D0%B1%D0%BA%D0%B0%3A+HTTPSConnectionPool%28host%3D%27api.telegram.org%27%2C+port%3D443%29%3A+Max+retries+exceeded+with+url%3A+%2Fbot6260404903%3AAAEU0Ax58ULUNvM9rBva_NR4cEIdTelM7OI%2FgetUpdates%3Foffset%3D337823247%26timeout%3D20+%28Caused+by+NewConnectionError%28%27%3Curllib3.connection.HTTPSConnection+object+at+0x104e68c70%3E%3A+Failed+to+establish+a+new+connection%3A+%5BErrno+8%5D+nodename+nor+servname+provided%2C+or+not+known%27%29%29 (Caused by NewConnectionError('<urllib3.connection.HTTPSConnection object at 0x104e788e0>: Failed to establish a new connection: [Errno 8] nodename nor servname provided, or not known'))
2023-05-22 21:50:59 - Error: HTTPSConnectionPool(host='api.telegram.org', port=443): Max retries exceeded with url: /bot6260404903:AAEU0Ax58ULUNvM9rBva_NR4cEIdTelM7OI/getUpdates?offset=337823247&timeout=20 (Caused by NewConnectionError('<urllib3.connection.HTTPSConnection object at 0x104e72820>: Failed to establish a new connection: [Errno 8] nodename nor servname provided, or not known'))
2023-05-22 21:50:59 - Failed to send error message: HTTPSConnectionPool(host='api.telegram.org', port=443): Max retries exceeded with url: /bot6260404903:AAEU0Ax58ULUNvM9rBva_NR4cEIdTelM7OI/sendMessage?chat_id=455162494&text=%D0%9F%D1%80%D0%BE%D0%B8%D0%B7%D0%BE%D1%88%D0%BB%D0%B0+%D0%BE%D1%88%D0%B8%D0%B1%D0%BA%D0%B0%3A+HTTPSConnectionPool%28host%3D%27api.telegram.org%27%2C+port%3D443%29%3A+Max+retries+exceeded+with+url%3A+%2Fbot6260404903%3AAAEU0Ax58ULUNvM9rBva_NR4cEIdTelM7OI%2FgetUpdates%3Foffset%3D337823247%26timeout%3D20+%28Caused+by+NewConnectionError%28%27%3Curllib3.connection.HTTPSConnection+object+at+0x104e72820%3E%3A+Failed+to+establish+a+new+connection%3A+%5BErrno+8%5D+nodename+nor+servname+provided%2C+or+not+known%27%29%29 (Caused by NewConnectionError('<urllib3.connection.HTTPSConnection object at 0x104e68eb0>: Failed to establish a new connection: [Errno 8] nodename nor servname provided, or not known'))
2023-05-22 21:51:25 - Error: HTTPSConnectionPool(host='api.telegram.org', port=443): Max retries exceeded with url: /bot6260404903:AAEU0Ax58ULUNvM9rBva_NR4cEIdTelM7OI/getUpdates?offset=337823247&timeout=20 (Caused by NewConnectionError('<urllib3.connection.HTTPSConnection object at 0x104e5ab80>: Failed to establish a new connection: [Errno 8] nodename nor servname provided, or not known'))
2023-05-22 21:51:25 - Failed to send error message: HTTPSConnectionPool(host='api.telegram.org', port=443): Max retries exceeded with url: /bot6260404903:AAEU0Ax58ULUNvM9rBva_NR4cEIdTelM7OI/sendMessage?chat_id=455162494&text=%D0%9F%D1%80%D0%BE%D0%B8%D0%B7%D0%BE%D1%88%D0%BB%D0%B0+%D0%BE%D1%88%D0%B8%D0%B1%D0%BA%D0%B0%3A+HTTPSConnectionPool%28host%3D%27api.telegram.org%27%2C+port%3D443%29%3A+Max+retries+exceeded+with+url%3A+%2Fbot6260404903%3AAAEU0Ax58ULUNvM9rBva_NR4cEIdTelM7OI%2FgetUpdates%3Foffset%3D337823247%26timeout%3D20+%28Caused+by+NewConnectionError%28%27%3Curllib3.connection.HTTPSConnection+object+at+0x104e5ab80%3E%3A+Failed+to+establish+a+new+connection%3A+%5BErrno+8%5D+nodename+nor+servname+provided%2C+or+not+known%27%29%29 (Caused by NewConnectionError('<urllib3.connection.HTTPSConnection object at 0x104e5a1f0>: Failed to establish a new connection: [Errno 8] nodename nor servname provided, or not known'))
2023-05-22 21:51:39 - Error: HTTPSConnectionPool(host='api.telegram.org', port=443): Max retries exceeded with url: /bot6260404903:AAEU0Ax58ULUNvM9rBva_NR4cEIdTelM7OI/getUpdates?offset=337823247&timeout=20 (Caused by NewConnectionError('<urllib3.connection.HTTPSConnection object at 0x104e5abe0>: Failed to establish a new connection: [Errno 8] nodename nor servname provided, or not known'))
2023-05-22 21:51:39 - Failed to send error message: HTTPSConnectionPool(host='api.telegram.org', port=443): Max retries exceeded with url: /bot6260404903:AAEU0Ax58ULUNvM9rBva_NR4cEIdTelM7OI/sendMessage?chat_id=455162494&text=%D0%9F%D1%80%D0%BE%D0%B8%D0%B7%D0%BE%D1%88%D0%BB%D0%B0+%D0%BE%D1%88%D0%B8%D0%B1%D0%BA%D0%B0%3A+HTTPSConnectionPool%28host%3D%27api.telegram.org%27%2C+port%3D443%29%3A+Max+retries+exceeded+with+url%3A+%2Fbot6260404903%3AAAEU0Ax58ULUNvM9rBva_NR4cEIdTelM7OI%2FgetUpdates%3Foffset%3D337823247%26timeout%3D20+%28Caused+by+NewConnectionError%28%27%3Curllib3.connection.HTTPSConnection+object+at+0x104e5abe0%3E%3A+Failed+to+establish+a+new+connection%3A+%5BErrno+8%5D+nodename+nor+servname+provided%2C+or+not+known%27%29%29 (Caused by NewConnectionError('<urllib3.connection.HTTPSConnection object at 0x104e5a880>: Failed to establish a new connection: [Errno 8] nodename nor servname provided, or not known'))
2023-05-22 21:52:09 - Error: HTTPSConnectionPool(host='api.telegram.org', port=443): Max retries exceeded with url: /bot6260404903:AAEU0Ax58ULUNvM9rBva_NR4cEIdTelM7OI/getUpdates?offset=337823247&timeout=20 (Caused by NewConnectionError('<urllib3.connection.HTTPSConnection object at 0x104e78eb0>: Failed to establish a new connection: [Errno 8] nodename nor servname provided, or not known'))
2023-05-22 21:52:09 - Failed to send error message: HTTPSConnectionPool(host='api.telegram.org', port=443): Max retries exceeded with url: /bot6260404903:AAEU0Ax58ULUNvM9rBva_NR4cEIdTelM7OI/sendMessage?chat_id=455162494&text=%D0%9F%D1%80%D0%BE%D0%B8%D0%B7%D0%BE%D1%88%D0%BB%D0%B0+%D0%BE%D1%88%D0%B8%D0%B1%D0%BA%D0%B0%3A+HTTPSConnectionPool%28host%3D%27api.telegram.org%27%2C+port%3D443%29%3A+Max+retries+exceeded+with+url%3A+%2Fbot6260404903%3AAAEU0Ax58ULUNvM9rBva_NR4cEIdTelM7OI%2FgetUpdates%3Foffset%3D337823247%26timeout%3D20+%28Caused+by+NewConnectionError%28%27%3Curllib3.connection.HTTPSConnection+object+at+0x104e78eb0%3E%3A+Failed+to+establish+a+new+connection%3A+%5BErrno+8%5D+nodename+nor+servname+provided%2C+or+not+known%27%29%29 (Caused by NewConnectionError('<urllib3.connection.HTTPSConnection object at 0x104e78b50>: Failed to establish a new connection: [Errno 8] nodename nor servname provided, or not known'))
2023-05-22 21:52:21 - Error: HTTPSConnectionPool(host='api.telegram.org', port=443): Max retries exceeded with url: /bot6260404903:AAEU0Ax58ULUNvM9rBva_NR4cEIdTelM7OI/getUpdates?offset=337823247&timeout=20 (Caused by NewConnectionError('<urllib3.connection.HTTPSConnection object at 0x104e4b220>: Failed to establish a new connection: [Errno 8] nodename nor servname provided, or not known'))
2023-05-22 21:52:21 - Failed to send error message: HTTPSConnectionPool(host='api.telegram.org', port=443): Max retries exceeded with url: /bot6260404903:AAEU0Ax58ULUNvM9rBva_NR4cEIdTelM7OI/sendMessage?chat_id=455162494&text=%D0%9F%D1%80%D0%BE%D0%B8%D0%B7%D0%BE%D1%88%D0%BB%D0%B0+%D0%BE%D1%88%D0%B8%D0%B1%D0%BA%D0%B0%3A+HTTPSConnectionPool%28host%3D%27api.telegram.org%27%2C+port%3D443%29%3A+Max+retries+exceeded+with+url%3A+%2Fbot6260404903%3AAAEU0Ax58ULUNvM9rBva_NR4cEIdTelM7OI%2FgetUpdates%3Foffset%3D337823247%26timeout%3D20+%28Caused+by+NewConnectionError%28%27%3Curllib3.connection.HTTPSConnection+object+at+0x104e4b220%3E%3A+Failed+to+establish+a+new+connection%3A+%5BErrno+8%5D+nodename+nor+servname+provided%2C+or+not+known%27%29%29 (Caused by NewConnectionError('<urllib3.connection.HTTPSConnection object at 0x104bc1730>: Failed to establish a new connection: [Errno 8] nodename nor servname provided, or not known'))
2023-05-22 21:52:36 - Error: HTTPSConnectionPool(host='api.telegram.org', port=443): Max retries exceeded with url: /bot6260404903:AAEU0Ax58ULUNvM9rBva_NR4cEIdTelM7OI/getUpdates?offset=337823247&timeout=20 (Caused by NewConnectionError('<urllib3.connection.HTTPSConnection object at 0x104e4b070>: Failed to establish a new connection: [Errno 8] nodename nor servname provided, or not known'))
2023-05-22 21:52:36 - Failed to send error message: HTTPSConnectionPool(host='api.telegram.org', port=443): Max retries exceeded with url: /bot6260404903:AAEU0Ax58ULUNvM9rBva_NR4cEIdTelM7OI/sendMessage?chat_id=455162494&text=%D0%9F%D1%80%D0%BE%D0%B8%D0%B7%D0%BE%D1%88%D0%BB%D0%B0+%D0%BE%D1%88%D0%B8%D0%B1%D0%BA%D0%B0%3A+HTTPSConnectionPool%28host%3D%27api.telegram.org%27%2C+port%3D443%29%3A+Max+retries+exceeded+with+url%3A+%2Fbot6260404903%3AAAEU0Ax58ULUNvM9rBva_NR4cEIdTelM7OI%2FgetUpdates%3Foffset%3D337823247%26timeout%3D20+%28Caused+by+NewConnectionError%28%27%3Curllib3.connection.HTTPSConnection+object+at+0x104e4b070%3E%3A+Failed+to+establish+a+new+connection%3A+%5BErrno+8%5D+nodename+nor+servname+provided%2C+or+not+known%27%29%29 (Caused by NewConnectionError('<urllib3.connection.HTTPSConnection object at 0x104e72880>: Failed to establish a new connection: [Errno 8] nodename nor servname provided, or not known'))
2023-05-22 21:52:48 - Error: HTTPSConnectionPool(host='api.telegram.org', port=443): Max retries exceeded with url: /bot6260404903:AAEU0Ax58ULUNvM9rBva_NR4cEIdTelM7OI/getUpdates?offset=337823247&timeout=20 (Caused by NewConnectionError('<urllib3.connection.HTTPSConnection object at 0x104e78370>: Failed to establish a new connection: [Errno 8] nodename nor servname provided, or not known'))
2023-05-22 21:52:48 - Failed to send error message: HTTPSConnectionPool(host='api.telegram.org', port=443): Max retries exceeded with url: /bot6260404903:AAEU0Ax58ULUNvM9rBva_NR4cEIdTelM7OI/sendMessage?chat_id=455162494&text=%D0%9F%D1%80%D0%BE%D0%B8%D0%B7%D0%BE%D1%88%D0%BB%D0%B0+%D0%BE%D1%88%D0%B8%D0%B1%D0%BA%D0%B0%3A+HTTPSConnectionPool%28host%3D%27api.telegram.org%27%2C+port%3D443%29%3A+Max+retries+exceeded+with+url%3A+%2Fbot6260404903%3AAAEU0Ax58ULUNvM9rBva_NR4cEIdTelM7OI%2FgetUpdates%3Foffset%3D337823247%26timeout%3D20+%28Caused+by+NewConnectionError%28%27%3Curllib3.connection.HTTPSConnection+object+at+0x104e78370%3E%3A+Failed+to+establish+a+new+connection%3A+%5BErrno+8%5D+nodename+nor+servname+provided%2C+or+not+known%27%29%29 (Caused by NewConnectionError('<urllib3.connection.HTTPSConnection object at 0x104e78550>: Failed to establish a new connection: [Errno 8] nodename nor servname provided, or not known'))
2023-05-22 21:53:43 - Error: HTTPSConnectionPool(host='api.telegram.org', port=443): Max retries exceeded with url: /bot6260404903:AAEU0Ax58ULUNvM9rBva_NR4cEIdTelM7OI/getUpdates?offset=337823247&timeout=20 (Caused by NewConnectionError('<urllib3.connection.HTTPSConnection object at 0x104e34e50>: Failed to establish a new connection: [Errno 8] nodename nor servname provided, or not known'))
2023-05-22 21:53:43 - Failed to send error message: HTTPSConnectionPool(host='api.telegram.org', port=443): Max retries exceeded with url: /bot6260404903:AAEU0Ax58ULUNvM9rBva_NR4cEIdTelM7OI/sendMessage?chat_id=455162494&text=%D0%9F%D1%80%D0%BE%D0%B8%D0%B7%D0%BE%D1%88%D0%BB%D0%B0+%D0%BE%D1%88%D0%B8%D0%B1%D0%BA%D0%B0%3A+HTTPSConnectionPool%28host%3D%27api.telegram.org%27%2C+port%3D443%29%3A+Max+retries+exceeded+with+url%3A+%2Fbot6260404903%3AAAEU0Ax58ULUNvM9rBva_NR4cEIdTelM7OI%2FgetUpdates%3Foffset%3D337823247%26timeout%3D20+%28Caused+by+NewConnectionError%28%27%3Curllib3.connection.HTTPSConnection+object+at+0x104e34e50%3E%3A+Failed+to+establish+a+new+connection%3A+%5BErrno+8%5D+nodename+nor+servname+provided%2C+or+not+known%27%29%29 (Caused by NewConnectionError('<urllib3.connection.HTTPSConnection object at 0x104e34c10>: Failed to establish a new connection: [Errno 8] nodename nor servname provided, or not known'))
2023-05-22 21:53:53 - Error: HTTPSConnectionPool(host='api.telegram.org', port=443): Max retries exceeded with url: /bot6260404903:AAEU0Ax58ULUNvM9rBva_NR4cEIdTelM7OI/getUpdates?offset=337823247&timeout=20 (Caused by NewConnectionError('<urllib3.connection.HTTPSConnection object at 0x104e688e0>: Failed to establish a new connection: [Errno 8] nodename nor servname provided, or not known'))
2023-05-22 21:53:53 - Failed to send error message: HTTPSConnectionPool(host='api.telegram.org', port=443): Max retries exceeded with url: /bot6260404903:AAEU0Ax58ULUNvM9rBva_NR4cEIdTelM7OI/sendMessage?chat_id=455162494&text=%D0%9F%D1%80%D0%BE%D0%B8%D0%B7%D0%BE%D1%88%D0%BB%D0%B0+%D0%BE%D1%88%D0%B8%D0%B1%D0%BA%D0%B0%3A+HTTPSConnectionPool%28host%3D%27api.telegram.org%27%2C+port%3D443%29%3A+Max+retries+exceeded+with+url%3A+%2Fbot6260404903%3AAAEU0Ax58ULUNvM9rBva_NR4cEIdTelM7OI%2FgetUpdates%3Foffset%3D337823247%26timeout%3D20+%28Caused+by+NewConnectionError%28%27%3Curllib3.connection.HTTPSConnection+object+at+0x104e688e0%3E%3A+Failed+to+establish+a+new+connection%3A+%5BErrno+8%5D+nodename+nor+servname+provided%2C+or+not+known%27%29%29 (Caused by NewConnectionError('<urllib3.connection.HTTPSConnection object at 0x104e34160>: Failed to establish a new connection: [Errno 8] nodename nor servname provided, or not known'))
2023-05-22 21:54:06 - Error: HTTPSConnectionPool(host='api.telegram.org', port=443): Max retries exceeded with url: /bot6260404903:AAEU0Ax58ULUNvM9rBva_NR4cEIdTelM7OI/getUpdates?offset=337823247&timeout=20 (Caused by NewConnectionError('<urllib3.connection.HTTPSConnection object at 0x104e788e0>: Failed to establish a new connection: [Errno 8] nodename nor servname provided, or not known'))
2023-05-22 21:54:06 - Failed to send error message: HTTPSConnectionPool(host='api.telegram.org', port=443): Max retries exceeded with url: /bot6260404903:AAEU0Ax58ULUNvM9rBva_NR4cEIdTelM7OI/sendMessage?chat_id=455162494&text=%D0%9F%D1%80%D0%BE%D0%B8%D0%B7%D0%BE%D1%88%D0%BB%D0%B0+%D0%BE%D1%88%D0%B8%D0%B1%D0%BA%D0%B0%3A+HTTPSConnectionPool%28host%3D%27api.telegram.org%27%2C+port%3D443%29%3A+Max+retries+exceeded+with+url%3A+%2Fbot6260404903%3AAAEU0Ax58ULUNvM9rBva_NR4cEIdTelM7OI%2FgetUpdates%3Foffset%3D337823247%26timeout%3D20+%28Caused+by+NewConnectionError%28%27%3Curllib3.connection.HTTPSConnection+object+at+0x104e788e0%3E%3A+Failed+to+establish+a+new+connection%3A+%5BErrno+8%5D+nodename+nor+servname+provided%2C+or+not+known%27%29%29 (Caused by NewConnectionError('<urllib3.connection.HTTPSConnection object at 0x104e722b0>: Failed to establish a new connection: [Errno 8] nodename nor servname provided, or not known'))
2023-05-22 21:55:39 - Error: HTTPSConnectionPool(host='api.telegram.org', port=443): Max retries exceeded with url: /bot6260404903:AAEU0Ax58ULUNvM9rBva_NR4cEIdTelM7OI/getUpdates?offset=337823247&timeout=20 (Caused by NewConnectionError('<urllib3.connection.HTTPSConnection object at 0x104b4cee0>: Failed to establish a new connection: [Errno 8] nodename nor servname provided, or not known'))
2023-05-22 21:55:39 - Failed to send error message: HTTPSConnectionPool(host='api.telegram.org', port=443): Max retries exceeded with url: /bot6260404903:AAEU0Ax58ULUNvM9rBva_NR4cEIdTelM7OI/sendMessage?chat_id=455162494&text=%D0%9F%D1%80%D0%BE%D0%B8%D0%B7%D0%BE%D1%88%D0%BB%D0%B0+%D0%BE%D1%88%D0%B8%D0%B1%D0%BA%D0%B0%3A+HTTPSConnectionPool%28host%3D%27api.telegram.org%27%2C+port%3D443%29%3A+Max+retries+exceeded+with+url%3A+%2Fbot6260404903%3AAAEU0Ax58ULUNvM9rBva_NR4cEIdTelM7OI%2FgetUpdates%3Foffset%3D337823247%26timeout%3D20+%28Caused+by+NewConnectionError%28%27%3Curllib3.connection.HTTPSConnection+object+at+0x104b4cee0%3E%3A+Failed+to+establish+a+new+connection%3A+%5BErrno+8%5D+nodename+nor+servname+provided%2C+or+not+known%27%29%29 (Caused by NewConnectionError('<urllib3.connection.HTTPSConnection object at 0x104b4cc70>: Failed to establish a new connection: [Errno 8] nodename nor servname provided, or not known'))
2023-05-22 21:57:05 - Error: HTTPSConnectionPool(host='api.telegram.org', port=443): Max retries exceeded with url: /bot6260404903:AAEU0Ax58ULUNvM9rBva_NR4cEIdTelM7OI/getUpdates?offset=337823247&timeout=20 (Caused by NewConnectionError('<urllib3.connection.HTTPSConnection object at 0x104bcea90>: Failed to establish a new connection: [Errno 8] nodename nor servname provided, or not known'))
2023-05-22 21:57:05 - Failed to send error message: HTTPSConnectionPool(host='api.telegram.org', port=443): Max retries exceeded with url: /bot6260404903:AAEU0Ax58ULUNvM9rBva_NR4cEIdTelM7OI/sendMessage?chat_id=455162494&text=%D0%9F%D1%80%D0%BE%D0%B8%D0%B7%D0%BE%D1%88%D0%BB%D0%B0+%D0%BE%D1%88%D0%B8%D0%B1%D0%BA%D0%B0%3A+HTTPSConnectionPool%28host%3D%27api.telegram.org%27%2C+port%3D443%29%3A+Max+retries+exceeded+with+url%3A+%2Fbot6260404903%3AAAEU0Ax58ULUNvM9rBva_NR4cEIdTelM7OI%2FgetUpdates%3Foffset%3D337823247%26timeout%3D20+%28Caused+by+NewConnectionError%28%27%3Curllib3.connection.HTTPSConnection+object+at+0x104bcea90%3E%3A+Failed+to+establish+a+new+connection%3A+%5BErrno+8%5D+nodename+nor+servname+provided%2C+or+not+known%27%29%29 (Caused by NewConnectionError('<urllib3.connection.HTTPSConnection object at 0x104b4cc40>: Failed to establish a new connection: [Errno 8] nodename nor servname provided, or not known'))
2023-05-22 21:58:47 - Error: HTTPSConnectionPool(host='api.telegram.org', port=443): Max retries exceeded with url: /bot6260404903:AAEU0Ax58ULUNvM9rBva_NR4cEIdTelM7OI/getUpdates?offset=337823247&timeout=20 (Caused by NewConnectionError('<urllib3.connection.HTTPSConnection object at 0x104e61190>: Failed to establish a new connection: [Errno 8] nodename nor servname provided, or not known'))
2023-05-22 21:58:47 - Failed to send error message: HTTPSConnectionPool(host='api.telegram.org', port=443): Max retries exceeded with url: /bot6260404903:AAEU0Ax58ULUNvM9rBva_NR4cEIdTelM7OI/sendMessage?chat_id=455162494&text=%D0%9F%D1%80%D0%BE%D0%B8%D0%B7%D0%BE%D1%88%D0%BB%D0%B0+%D0%BE%D1%88%D0%B8%D0%B1%D0%BA%D0%B0%3A+HTTPSConnectionPool%28host%3D%27api.telegram.org%27%2C+port%3D443%29%3A+Max+retries+exceeded+with+url%3A+%2Fbot6260404903%3AAAEU0Ax58ULUNvM9rBva_NR4cEIdTelM7OI%2FgetUpdates%3Foffset%3D337823247%26timeout%3D20+%28Caused+by+NewConnectionError%28%27%3Curllib3.connection.HTTPSConnection+object+at+0x104e61190%3E%3A+Failed+to+establish+a+new+connection%3A+%5BErrno+8%5D+nodename+nor+servname+provided%2C+or+not+known%27%29%29 (Caused by NewConnectionError('<urllib3.connection.HTTPSConnection object at 0x104e78a60>: Failed to establish a new connection: [Errno 8] nodename nor servname provided, or not known'))
2023-05-22 22:00:12 - Error: HTTPSConnectionPool(host='api.telegram.org', port=443): Max retries exceeded with url: /bot6260404903:AAEU0Ax58ULUNvM9rBva_NR4cEIdTelM7OI/getUpdates?offset=337823247&timeout=20 (Caused by NewConnectionError('<urllib3.connection.HTTPSConnection object at 0x104cab2e0>: Failed to establish a new connection: [Errno 8] nodename nor servname provided, or not known'))
2023-05-22 22:00:12 - Failed to send error message: HTTPSConnectionPool(host='api.telegram.org', port=443): Max retries exceeded with url: /bot6260404903:AAEU0Ax58ULUNvM9rBva_NR4cEIdTelM7OI/sendMessage?chat_id=455162494&text=%D0%9F%D1%80%D0%BE%D0%B8%D0%B7%D0%BE%D1%88%D0%BB%D0%B0+%D0%BE%D1%88%D0%B8%D0%B1%D0%BA%D0%B0%3A+HTTPSConnectionPool%28host%3D%27api.telegram.org%27%2C+port%3D443%29%3A+Max+retries+exceeded+with+url%3A+%2Fbot6260404903%3AAAEU0Ax58ULUNvM9rBva_NR4cEIdTelM7OI%2FgetUpdates%3Foffset%3D337823247%26timeout%3D20+%28Caused+by+NewConnectionError%28%27%3Curllib3.connection.HTTPSConnection+object+at+0x104cab2e0%3E%3A+Failed+to+establish+a+new+connection%3A+%5BErrno+8%5D+nodename+nor+servname+provided%2C+or+not+known%27%29%29 (Caused by NewConnectionError('<urllib3.connection.HTTPSConnection object at 0x104cab1c0>: Failed to establish a new connection: [Errno 8] nodename nor servname provided, or not known'))
2023-05-22 22:01:55 - Error: HTTPSConnectionPool(host='api.telegram.org', port=443): Max retries exceeded with url: /bot6260404903:AAEU0Ax58ULUNvM9rBva_NR4cEIdTelM7OI/getUpdates?offset=337823247&timeout=20 (Caused by NewConnectionError('<urllib3.connection.HTTPSConnection object at 0x104c4d580>: Failed to establish a new connection: [Errno 8] nodename nor servname provided, or not known'))
2023-05-22 22:01:55 - Failed to send error message: HTTPSConnectionPool(host='api.telegram.org', port=443): Max retries exceeded with url: /bot6260404903:AAEU0Ax58ULUNvM9rBva_NR4cEIdTelM7OI/sendMessage?chat_id=455162494&text=%D0%9F%D1%80%D0%BE%D0%B8%D0%B7%D0%BE%D1%88%D0%BB%D0%B0+%D0%BE%D1%88%D0%B8%D0%B1%D0%BA%D0%B0%3A+HTTPSConnectionPool%28host%3D%27api.telegram.org%27%2C+port%3D443%29%3A+Max+retries+exceeded+with+url%3A+%2Fbot6260404903%3AAAEU0Ax58ULUNvM9rBva_NR4cEIdTelM7OI%2FgetUpdates%3Foffset%3D337823247%26timeout%3D20+%28Caused+by+NewConnectionError%28%27%3Curllib3.connection.HTTPSConnection+object+at+0x104c4d580%3E%3A+Failed+to+establish+a+new+connection%3A+%5BErrno+8%5D+nodename+nor+servname+provided%2C+or+not+known%27%29%29 (Caused by NewConnectionError('<urllib3.connection.HTTPSConnection object at 0x104e5afa0>: Failed to establish a new connection: [Errno 8] nodename nor servname provided, or not known'))
2023-05-22 22:03:07 - Error: HTTPSConnectionPool(host='api.telegram.org', port=443): Max retries exceeded with url: /bot6260404903:AAEU0Ax58ULUNvM9rBva_NR4cEIdTelM7OI/getUpdates?offset=337823247&timeout=20 (Caused by NewConnectionError('<urllib3.connection.HTTPSConnection object at 0x104e61130>: Failed to establish a new connection: [Errno 8] nodename nor servname provided, or not known'))
2023-05-22 22:03:07 - Failed to send error message: HTTPSConnectionPool(host='api.telegram.org', port=443): Max retries exceeded with url: /bot6260404903:AAEU0Ax58ULUNvM9rBva_NR4cEIdTelM7OI/sendMessage?chat_id=455162494&text=%D0%9F%D1%80%D0%BE%D0%B8%D0%B7%D0%BE%D1%88%D0%BB%D0%B0+%D0%BE%D1%88%D0%B8%D0%B1%D0%BA%D0%B0%3A+HTTPSConnectionPool%28host%3D%27api.telegram.org%27%2C+port%3D443%29%3A+Max+retries+exceeded+with+url%3A+%2Fbot6260404903%3AAAEU0Ax58ULUNvM9rBva_NR4cEIdTelM7OI%2FgetUpdates%3Foffset%3D337823247%26timeout%3D20+%28Caused+by+NewConnectionError%28%27%3Curllib3.connection.HTTPSConnection+object+at+0x104e61130%3E%3A+Failed+to+establish+a+new+connection%3A+%5BErrno+8%5D+nodename+nor+servname+provided%2C+or+not+known%27%29%29 (Caused by NewConnectionError('<urllib3.connection.HTTPSConnection object at 0x104e613d0>: Failed to establish a new connection: [Errno 8] nodename nor servname provided, or not known'))
2023-05-22 22:05:04 - Error: HTTPSConnectionPool(host='api.telegram.org', port=443): Max retries exceeded with url: /bot6260404903:AAEU0Ax58ULUNvM9rBva_NR4cEIdTelM7OI/getUpdates?offset=337823247&timeout=20 (Caused by NewConnectionError('<urllib3.connection.HTTPSConnection object at 0x104e726a0>: Failed to establish a new connection: [Errno 8] nodename nor servname provided, or not known'))
2023-05-22 22:05:04 - Failed to send error message: HTTPSConnectionPool(host='api.telegram.org', port=443): Max retries exceeded with url: /bot6260404903:AAEU0Ax58ULUNvM9rBva_NR4cEIdTelM7OI/sendMessage?chat_id=455162494&text=%D0%9F%D1%80%D0%BE%D0%B8%D0%B7%D0%BE%D1%88%D0%BB%D0%B0+%D0%BE%D1%88%D0%B8%D0%B1%D0%BA%D0%B0%3A+HTTPSConnectionPool%28host%3D%27api.telegram.org%27%2C+port%3D443%29%3A+Max+retries+exceeded+with+url%3A+%2Fbot6260404903%3AAAEU0Ax58ULUNvM9rBva_NR4cEIdTelM7OI%2FgetUpdates%3Foffset%3D337823247%26timeout%3D20+%28Caused+by+NewConnectionError%28%27%3Curllib3.connection.HTTPSConnection+object+at+0x104e726a0%3E%3A+Failed+to+establish+a+new+connection%3A+%5BErrno+8%5D+nodename+nor+servname+provided%2C+or+not+known%27%29%29 (Caused by NewConnectionError('<urllib3.connection.HTTPSConnection object at 0x104e348e0>: Failed to establish a new connection: [Errno 8] nodename nor servname provided, or not known'))
2023-05-22 22:05:14 - Error: HTTPSConnectionPool(host='api.telegram.org', port=443): Max retries exceeded with url: /bot6260404903:AAEU0Ax58ULUNvM9rBva_NR4cEIdTelM7OI/getUpdates?offset=337823247&timeout=20 (Caused by NewConnectionError('<urllib3.connection.HTTPSConnection object at 0x104c4d940>: Failed to establish a new connection: [Errno 8] nodename nor servname provided, or not known'))
2023-05-22 22:05:14 - Failed to send error message: HTTPSConnectionPool(host='api.telegram.org', port=443): Max retries exceeded with url: /bot6260404903:AAEU0Ax58ULUNvM9rBva_NR4cEIdTelM7OI/sendMessage?chat_id=455162494&text=%D0%9F%D1%80%D0%BE%D0%B8%D0%B7%D0%BE%D1%88%D0%BB%D0%B0+%D0%BE%D1%88%D0%B8%D0%B1%D0%BA%D0%B0%3A+HTTPSConnectionPool%28host%3D%27api.telegram.org%27%2C+port%3D443%29%3A+Max+retries+exceeded+with+url%3A+%2Fbot6260404903%3AAAEU0Ax58ULUNvM9rBva_NR4cEIdTelM7OI%2FgetUpdates%3Foffset%3D337823247%26timeout%3D20+%28Caused+by+NewConnectionError%28%27%3Curllib3.connection.HTTPSConnection+object+at+0x104c4d940%3E%3A+Failed+to+establish+a+new+connection%3A+%5BErrno+8%5D+nodename+nor+servname+provided%2C+or+not+known%27%29%29 (Caused by NewConnectionError('<urllib3.connection.HTTPSConnection object at 0x104b4cf40>: Failed to establish a new connection: [Errno 8] nodename nor servname provided, or not known'))
2023-05-22 22:06:25 - Error: HTTPSConnectionPool(host='api.telegram.org', port=443): Max retries exceeded with url: /bot6260404903:AAEU0Ax58ULUNvM9rBva_NR4cEIdTelM7OI/getUpdates?offset=337823247&timeout=20 (Caused by NewConnectionError('<urllib3.connection.HTTPSConnection object at 0x104e78250>: Failed to establish a new connection: [Errno 8] nodename nor servname provided, or not known'))
2023-05-22 22:06:25 - Failed to send error message: HTTPSConnectionPool(host='api.telegram.org', port=443): Max retries exceeded with url: /bot6260404903:AAEU0Ax58ULUNvM9rBva_NR4cEIdTelM7OI/sendMessage?chat_id=455162494&text=%D0%9F%D1%80%D0%BE%D0%B8%D0%B7%D0%BE%D1%88%D0%BB%D0%B0+%D0%BE%D1%88%D0%B8%D0%B1%D0%BA%D0%B0%3A+HTTPSConnectionPool%28host%3D%27api.telegram.org%27%2C+port%3D443%29%3A+Max+retries+exceeded+with+url%3A+%2Fbot6260404903%3AAAEU0Ax58ULUNvM9rBva_NR4cEIdTelM7OI%2FgetUpdates%3Foffset%3D337823247%26timeout%3D20+%28Caused+by+NewConnectionError%28%27%3Curllib3.connection.HTTPSConnection+object+at+0x104e78250%3E%3A+Failed+to+establish+a+new+connection%3A+%5BErrno+8%5D+nodename+nor+servname+provided%2C+or+not+known%27%29%29 (Caused by NewConnectionError('<urllib3.connection.HTTPSConnection object at 0x104e789d0>: Failed to establish a new connection: [Errno 8] nodename nor servname provided, or not known'))
2023-05-22 22:08:20 - Error: HTTPSConnectionPool(host='api.telegram.org', port=443): Max retries exceeded with url: /bot6260404903:AAEU0Ax58ULUNvM9rBva_NR4cEIdTelM7OI/getUpdates?offset=337823247&timeout=20 (Caused by NewConnectionError('<urllib3.connection.HTTPSConnection object at 0x104cb4100>: Failed to establish a new connection: [Errno 8] nodename nor servname provided, or not known'))
2023-05-22 22:08:20 - Failed to send error message: HTTPSConnectionPool(host='api.telegram.org', port=443): Max retries exceeded with url: /bot6260404903:AAEU0Ax58ULUNvM9rBva_NR4cEIdTelM7OI/sendMessage?chat_id=455162494&text=%D0%9F%D1%80%D0%BE%D0%B8%D0%B7%D0%BE%D1%88%D0%BB%D0%B0+%D0%BE%D1%88%D0%B8%D0%B1%D0%BA%D0%B0%3A+HTTPSConnectionPool%28host%3D%27api.telegram.org%27%2C+port%3D443%29%3A+Max+retries+exceeded+with+url%3A+%2Fbot6260404903%3AAAEU0Ax58ULUNvM9rBva_NR4cEIdTelM7OI%2FgetUpdates%3Foffset%3D337823247%26timeout%3D20+%28Caused+by+NewConnectionError%28%27%3Curllib3.connection.HTTPSConnection+object+at+0x104cb4100%3E%3A+Failed+to+establish+a+new+connection%3A+%5BErrno+8%5D+nodename+nor+servname+provided%2C+or+not+known%27%29%29 (Caused by NewConnectionError('<urllib3.connection.HTTPSConnection object at 0x104cb4940>: Failed to establish a new connection: [Errno 8] nodename nor servname provided, or not known'))
2023-05-22 22:09:30 - Error: HTTPSConnectionPool(host='api.telegram.org', port=443): Max retries exceeded with url: /bot6260404903:AAEU0Ax58ULUNvM9rBva_NR4cEIdTelM7OI/getUpdates?offset=337823247&timeout=20 (Caused by NewConnectionError('<urllib3.connection.HTTPSConnection object at 0x104e344f0>: Failed to establish a new connection: [Errno 8] nodename nor servname provided, or not known'))
2023-05-22 22:09:30 - Failed to send error message: HTTPSConnectionPool(host='api.telegram.org', port=443): Max retries exceeded with url: /bot6260404903:AAEU0Ax58ULUNvM9rBva_NR4cEIdTelM7OI/sendMessage?chat_id=455162494&text=%D0%9F%D1%80%D0%BE%D0%B8%D0%B7%D0%BE%D1%88%D0%BB%D0%B0+%D0%BE%D1%88%D0%B8%D0%B1%D0%BA%D0%B0%3A+HTTPSConnectionPool%28host%3D%27api.telegram.org%27%2C+port%3D443%29%3A+Max+retries+exceeded+with+url%3A+%2Fbot6260404903%3AAAEU0Ax58ULUNvM9rBva_NR4cEIdTelM7OI%2FgetUpdates%3Foffset%3D337823247%26timeout%3D20+%28Caused+by+NewConnectionError%28%27%3Curllib3.connection.HTTPSConnection+object+at+0x104e344f0%3E%3A+Failed+to+establish+a+new+connection%3A+%5BErrno+8%5D+nodename+nor+servname+provided%2C+or+not+known%27%29%29 (Caused by NewConnectionError('<urllib3.connection.HTTPSConnection object at 0x104e5a9d0>: Failed to establish a new connection: [Errno 8] nodename nor servname provided, or not known'))
2023-05-22 22:11:25 - Error: HTTPSConnectionPool(host='api.telegram.org', port=443): Max retries exceeded with url: /bot6260404903:AAEU0Ax58ULUNvM9rBva_NR4cEIdTelM7OI/getUpdates?offset=337823247&timeout=20 (Caused by NewConnectionError('<urllib3.connection.HTTPSConnection object at 0x104e78370>: Failed to establish a new connection: [Errno 8] nodename nor servname provided, or not known'))
2023-05-22 22:11:25 - Failed to send error message: HTTPSConnectionPool(host='api.telegram.org', port=443): Max retries exceeded with url: /bot6260404903:AAEU0Ax58ULUNvM9rBva_NR4cEIdTelM7OI/sendMessage?chat_id=455162494&text=%D0%9F%D1%80%D0%BE%D0%B8%D0%B7%D0%BE%D1%88%D0%BB%D0%B0+%D0%BE%D1%88%D0%B8%D0%B1%D0%BA%D0%B0%3A+HTTPSConnectionPool%28host%3D%27api.telegram.org%27%2C+port%3D443%29%3A+Max+retries+exceeded+with+url%3A+%2Fbot6260404903%3AAAEU0Ax58ULUNvM9rBva_NR4cEIdTelM7OI%2FgetUpdates%3Foffset%3D337823247%26timeout%3D20+%28Caused+by+NewConnectionError%28%27%3Curllib3.connection.HTTPSConnection+object+at+0x104e78370%3E%3A+Failed+to+establish+a+new+connection%3A+%5BErrno+8%5D+nodename+nor+servname+provided%2C+or+not+known%27%29%29 (Caused by NewConnectionError('<urllib3.connection.HTTPSConnection object at 0x104e780a0>: Failed to establish a new connection: [Errno 8] nodename nor servname provided, or not known'))
2023-05-22 22:12:35 - Error: HTTPSConnectionPool(host='api.telegram.org', port=443): Max retries exceeded with url: /bot6260404903:AAEU0Ax58ULUNvM9rBva_NR4cEIdTelM7OI/getUpdates?offset=337823247&timeout=20 (Caused by NewConnectionError('<urllib3.connection.HTTPSConnection object at 0x104e81e20>: Failed to establish a new connection: [Errno 8] nodename nor servname provided, or not known'))
2023-05-22 22:12:35 - Failed to send error message: HTTPSConnectionPool(host='api.telegram.org', port=443): Max retries exceeded with url: /bot6260404903:AAEU0Ax58ULUNvM9rBva_NR4cEIdTelM7OI/sendMessage?chat_id=455162494&text=%D0%9F%D1%80%D0%BE%D0%B8%D0%B7%D0%BE%D1%88%D0%BB%D0%B0+%D0%BE%D1%88%D0%B8%D0%B1%D0%BA%D0%B0%3A+HTTPSConnectionPool%28host%3D%27api.telegram.org%27%2C+port%3D443%29%3A+Max+retries+exceeded+with+url%3A+%2Fbot6260404903%3AAAEU0Ax58ULUNvM9rBva_NR4cEIdTelM7OI%2FgetUpdates%3Foffset%3D337823247%26timeout%3D20+%28Caused+by+NewConnectionError%28%27%3Curllib3.connection.HTTPSConnection+object+at+0x104e81e20%3E%3A+Failed+to+establish+a+new+connection%3A+%5BErrno+8%5D+nodename+nor+servname+provided%2C+or+not+known%27%29%29 (Caused by NewConnectionError('<urllib3.connection.HTTPSConnection object at 0x104e54100>: Failed to establish a new connection: [Errno 8] nodename nor servname provided, or not known'))
2023-05-22 22:13:29 - Error: HTTPSConnectionPool(host='api.telegram.org', port=443): Max retries exceeded with url: /bot6260404903:AAEU0Ax58ULUNvM9rBva_NR4cEIdTelM7OI/getUpdates?offset=337823247&timeout=20 (Caused by NewConnectionError('<urllib3.connection.HTTPSConnection object at 0x104e81e80>: Failed to establish a new connection: [Errno 8] nodename nor servname provided, or not known'))
2023-05-22 22:13:29 - Failed to send error message: HTTPSConnectionPool(host='api.telegram.org', port=443): Max retries exceeded with url: /bot6260404903:AAEU0Ax58ULUNvM9rBva_NR4cEIdTelM7OI/sendMessage?chat_id=455162494&text=%D0%9F%D1%80%D0%BE%D0%B8%D0%B7%D0%BE%D1%88%D0%BB%D0%B0+%D0%BE%D1%88%D0%B8%D0%B1%D0%BA%D0%B0%3A+HTTPSConnectionPool%28host%3D%27api.telegram.org%27%2C+port%3D443%29%3A+Max+retries+exceeded+with+url%3A+%2Fbot6260404903%3AAAEU0Ax58ULUNvM9rBva_NR4cEIdTelM7OI%2FgetUpdates%3Foffset%3D337823247%26timeout%3D20+%28Caused+by+NewConnectionError%28%27%3Curllib3.connection.HTTPSConnection+object+at+0x104e81e80%3E%3A+Failed+to+establish+a+new+connection%3A+%5BErrno+8%5D+nodename+nor+servname+provided%2C+or+not+known%27%29%29 (Caused by NewConnectionError('<urllib3.connection.HTTPSConnection object at 0x104b4ccd0>: Failed to establish a new connection: [Errno 8] nodename nor servname provided, or not known'))
2023-05-22 22:14:30 - Error: HTTPSConnectionPool(host='api.telegram.org', port=443): Max retries exceeded with url: /bot6260404903:AAEU0Ax58ULUNvM9rBva_NR4cEIdTelM7OI/getUpdates?offset=337823247&timeout=20 (Caused by NewConnectionError('<urllib3.connection.HTTPSConnection object at 0x104e61280>: Failed to establish a new connection: [Errno 8] nodename nor servname provided, or not known'))
2023-05-22 22:14:30 - Failed to send error message: HTTPSConnectionPool(host='api.telegram.org', port=443): Max retries exceeded with url: /bot6260404903:AAEU0Ax58ULUNvM9rBva_NR4cEIdTelM7OI/sendMessage?chat_id=455162494&text=%D0%9F%D1%80%D0%BE%D0%B8%D0%B7%D0%BE%D1%88%D0%BB%D0%B0+%D0%BE%D1%88%D0%B8%D0%B1%D0%BA%D0%B0%3A+HTTPSConnectionPool%28host%3D%27api.telegram.org%27%2C+port%3D443%29%3A+Max+retries+exceeded+with+url%3A+%2Fbot6260404903%3AAAEU0Ax58ULUNvM9rBva_NR4cEIdTelM7OI%2FgetUpdates%3Foffset%3D337823247%26timeout%3D20+%28Caused+by+NewConnectionError%28%27%3Curllib3.connection.HTTPSConnection+object+at+0x104e61280%3E%3A+Failed+to+establish+a+new+connection%3A+%5BErrno+8%5D+nodename+nor+servname+provided%2C+or+not+known%27%29%29 (Caused by NewConnectionError('<urllib3.connection.HTTPSConnection object at 0x104cb4a60>: Failed to establish a new connection: [Errno 8] nodename nor servname provided, or not known'))
2023-05-22 22:14:40 - Error: HTTPSConnectionPool(host='api.telegram.org', port=443): Max retries exceeded with url: /bot6260404903:AAEU0Ax58ULUNvM9rBva_NR4cEIdTelM7OI/getUpdates?offset=337823247&timeout=20 (Caused by NewConnectionError('<urllib3.connection.HTTPSConnection object at 0x104e4c250>: Failed to establish a new connection: [Errno 8] nodename nor servname provided, or not known'))
2023-05-22 22:14:40 - Failed to send error message: HTTPSConnectionPool(host='api.telegram.org', port=443): Max retries exceeded with url: /bot6260404903:AAEU0Ax58ULUNvM9rBva_NR4cEIdTelM7OI/sendMessage?chat_id=455162494&text=%D0%9F%D1%80%D0%BE%D0%B8%D0%B7%D0%BE%D1%88%D0%BB%D0%B0+%D0%BE%D1%88%D0%B8%D0%B1%D0%BA%D0%B0%3A+HTTPSConnectionPool%28host%3D%27api.telegram.org%27%2C+port%3D443%29%3A+Max+retries+exceeded+with+url%3A+%2Fbot6260404903%3AAAEU0Ax58ULUNvM9rBva_NR4cEIdTelM7OI%2FgetUpdates%3Foffset%3D337823247%26timeout%3D20+%28Caused+by+NewConnectionError%28%27%3Curllib3.connection.HTTPSConnection+object+at+0x104e4c250%3E%3A+Failed+to+establish+a+new+connection%3A+%5BErrno+8%5D+nodename+nor+servname+provided%2C+or+not+known%27%29%29 (Caused by NewConnectionError('<urllib3.connection.HTTPSConnection object at 0x104e4c6a0>: Failed to establish a new connection: [Errno 8] nodename nor servname provided, or not known'))
2023-05-22 22:15:50 - Error: HTTPSConnectionPool(host='api.telegram.org', port=443): Max retries exceeded with url: /bot6260404903:AAEU0Ax58ULUNvM9rBva_NR4cEIdTelM7OI/getUpdates?offset=337823247&timeout=20 (Caused by NewConnectionError('<urllib3.connection.HTTPSConnection object at 0x104cab910>: Failed to establish a new connection: [Errno 8] nodename nor servname provided, or not known'))
2023-05-22 22:15:50 - Failed to send error message: HTTPSConnectionPool(host='api.telegram.org', port=443): Max retries exceeded with url: /bot6260404903:AAEU0Ax58ULUNvM9rBva_NR4cEIdTelM7OI/sendMessage?chat_id=455162494&text=%D0%9F%D1%80%D0%BE%D0%B8%D0%B7%D0%BE%D1%88%D0%BB%D0%B0+%D0%BE%D1%88%D0%B8%D0%B1%D0%BA%D0%B0%3A+HTTPSConnectionPool%28host%3D%27api.telegram.org%27%2C+port%3D443%29%3A+Max+retries+exceeded+with+url%3A+%2Fbot6260404903%3AAAEU0Ax58ULUNvM9rBva_NR4cEIdTelM7OI%2FgetUpdates%3Foffset%3D337823247%26timeout%3D20+%28Caused+by+NewConnectionError%28%27%3Curllib3.connection.HTTPSConnection+object+at+0x104cab910%3E%3A+Failed+to+establish+a+new+connection%3A+%5BErrno+8%5D+nodename+nor+servname+provided%2C+or+not+known%27%29%29 (Caused by NewConnectionError('<urllib3.connection.HTTPSConnection object at 0x104c4d610>: Failed to establish a new connection: [Errno 8] nodename nor servname provided, or not known'))
2023-05-22 22:17:31 - Error: HTTPSConnectionPool(host='api.telegram.org', port=443): Max retries exceeded with url: /bot6260404903:AAEU0Ax58ULUNvM9rBva_NR4cEIdTelM7OI/getUpdates?offset=337823247&timeout=20 (Caused by NewConnectionError('<urllib3.connection.HTTPSConnection object at 0x104c43fd0>: Failed to establish a new connection: [Errno 8] nodename nor servname provided, or not known'))
2023-05-22 22:17:31 - Failed to send error message: HTTPSConnectionPool(host='api.telegram.org', port=443): Max retries exceeded with url: /bot6260404903:AAEU0Ax58ULUNvM9rBva_NR4cEIdTelM7OI/sendMessage?chat_id=455162494&text=%D0%9F%D1%80%D0%BE%D0%B8%D0%B7%D0%BE%D1%88%D0%BB%D0%B0+%D0%BE%D1%88%D0%B8%D0%B1%D0%BA%D0%B0%3A+HTTPSConnectionPool%28host%3D%27api.telegram.org%27%2C+port%3D443%29%3A+Max+retries+exceeded+with+url%3A+%2Fbot6260404903%3AAAEU0Ax58ULUNvM9rBva_NR4cEIdTelM7OI%2FgetUpdates%3Foffset%3D337823247%26timeout%3D20+%28Caused+by+NewConnectionError%28%27%3Curllib3.connection.HTTPSConnection+object+at+0x104c43fd0%3E%3A+Failed+to+establish+a+new+connection%3A+%5BErrno+8%5D+nodename+nor+servname+provided%2C+or+not+known%27%29%29 (Caused by NewConnectionError('<urllib3.connection.HTTPSConnection object at 0x104b4cca0>: Failed to establish a new connection: [Errno 8] nodename nor servname provided, or not known'))
2023-05-22 22:18:25 - Error: HTTPSConnectionPool(host='api.telegram.org', port=443): Read timed out. (read timeout=25)
2023-05-22 22:42:37 - Error: HTTPSConnectionPool(host='api.telegram.org', port=443): Read timed out. (read timeout=25)
2023-05-23 18:39:54 - Error: HTTPSConnectionPool(host='api.telegram.org', port=443): Read timed out. (read timeout=25)
2023-05-23 20:00:02 - Error: HTTPSConnectionPool(host='api.telegram.org', port=443): Read timed out. (read timeout=25)
2023-05-23 20:04:48 - Error: HTTPSConnectionPool(host='api.telegram.org', port=443): Read timed out. (read timeout=25)
2023-05-24 01:25:43 - Error: HTTPSConnectionPool(host='api.telegram.org', port=443): Read timed out. (read timeout=25)
2023-05-24 16:28:04 - Error: 760923861
