ERROR:root:Error: Тестовое исключение
ERROR:root:Error: Тестовое исключение
2023-05-08 18:57:15 - Error: Тестовое исключение
2023-05-08 18:58:06 - Error: Тестовое исключение
2023-05-08 19:53:44 - Error: HTTPSConnectionPool(host='api.telegram.org', port=443): Read timed out. (read timeout=25)
2023-05-08 21:00:34 - Error: list indices must be integers or slices, not str
2023-05-08 21:02:49 - Error: 'dict' object has no attribute 'tasks'
2023-05-08 21:09:54 - Error: list indices must be integers or slices, not str
2023-05-08 21:14:08 - Error: '_io.BufferedReader' object has no attribute 'get'
2023-05-08 21:16:12 - Error: 'bytes' object has no attribute 'get'
2023-05-08 21:19:48 - Error: 'bytes' object has no attribute 'get'
2023-05-08 21:21:56 - Error: Failed. Response status: 402. Response message: Payment Required. Error message: {"message":"You have started too many jobs at once","code":"PARALLEL_JOB_LIMIT_EXCEEDED"}
2023-05-08 21:33:56 - Error: create_document() missing 1 required positional argument: 'file_format'
2023-05-08 21:37:41 - Error: [Errno 2] No such file or directory: 'output_files/title_page_6260404903.pdf'
2023-05-09 00:39:25 - Threaded polling exception: A request to the Telegram API was unsuccessful. Error code: 400. Description: Bad Request: can't parse entities: Can't find end tag corresponding to start tag b
2023-05-09 00:39:25 - Exception traceback:
Traceback (most recent call last):
  File "/Users/shapovv/PycharmProjects/Radost/venv/lib/python3.9/site-packages/telebot/__init__.py", line 1074, in __threaded_polling
    self.worker_pool.raise_exceptions()
  File "/Users/shapovv/PycharmProjects/Radost/venv/lib/python3.9/site-packages/telebot/util.py", line 147, in raise_exceptions
    raise self.exception_info
  File "/Users/shapovv/PycharmProjects/Radost/venv/lib/python3.9/site-packages/telebot/util.py", line 90, in run
    task(*args, **kwargs)
  File "/Users/shapovv/PycharmProjects/Radost/venv/lib/python3.9/site-packages/telebot/__init__.py", line 6720, in _run_middlewares_and_handler
    result = handler['function'](message)
  File "/Users/shapovv/PycharmProjects/Radost/bot_test.py", line 182, in document_template_handler
    bot.send_message(call.message.chat.id,
  File "/Users/shapovv/PycharmProjects/Radost/venv/lib/python3.9/site-packages/telebot/__init__.py", line 1549, in send_message
    apihelper.send_message(
  File "/Users/shapovv/PycharmProjects/Radost/venv/lib/python3.9/site-packages/telebot/apihelper.py", line 264, in send_message
    return _make_request(token, method_url, params=payload, method='post')
  File "/Users/shapovv/PycharmProjects/Radost/venv/lib/python3.9/site-packages/telebot/apihelper.py", line 162, in _make_request
    json_result = _check_result(method_name, result)
  File "/Users/shapovv/PycharmProjects/Radost/venv/lib/python3.9/site-packages/telebot/apihelper.py", line 189, in _check_result
    raise ApiTelegramException(method_name, result, result_json)
telebot.apihelper.ApiTelegramException: A request to the Telegram API was unsuccessful. Error code: 400. Description: Bad Request: can't parse entities: Can't find end tag corresponding to start tag b

2023-05-09 00:39:58 - Threaded polling exception: A request to the Telegram API was unsuccessful. Error code: 400. Description: Bad Request: can't parse entities: Can't find end tag corresponding to start tag b
2023-05-09 00:39:58 - Exception traceback:
Traceback (most recent call last):
  File "/Users/shapovv/PycharmProjects/Radost/venv/lib/python3.9/site-packages/telebot/__init__.py", line 1074, in __threaded_polling
    self.worker_pool.raise_exceptions()
  File "/Users/shapovv/PycharmProjects/Radost/venv/lib/python3.9/site-packages/telebot/util.py", line 147, in raise_exceptions
    raise self.exception_info
  File "/Users/shapovv/PycharmProjects/Radost/venv/lib/python3.9/site-packages/telebot/util.py", line 90, in run
    task(*args, **kwargs)
  File "/Users/shapovv/PycharmProjects/Radost/venv/lib/python3.9/site-packages/telebot/__init__.py", line 6720, in _run_middlewares_and_handler
    result = handler['function'](message)
  File "/Users/shapovv/PycharmProjects/Radost/bot_test.py", line 182, in document_template_handler
    bot.send_message(call.message.chat.id,
  File "/Users/shapovv/PycharmProjects/Radost/venv/lib/python3.9/site-packages/telebot/__init__.py", line 1549, in send_message
    apihelper.send_message(
  File "/Users/shapovv/PycharmProjects/Radost/venv/lib/python3.9/site-packages/telebot/apihelper.py", line 264, in send_message
    return _make_request(token, method_url, params=payload, method='post')
  File "/Users/shapovv/PycharmProjects/Radost/venv/lib/python3.9/site-packages/telebot/apihelper.py", line 162, in _make_request
    json_result = _check_result(method_name, result)
  File "/Users/shapovv/PycharmProjects/Radost/venv/lib/python3.9/site-packages/telebot/apihelper.py", line 189, in _check_result
    raise ApiTelegramException(method_name, result, result_json)
telebot.apihelper.ApiTelegramException: A request to the Telegram API was unsuccessful. Error code: 400. Description: Bad Request: can't parse entities: Can't find end tag corresponding to start tag b

2023-05-09 01:20:58 - Error: HTTPSConnectionPool(host='api.telegram.org', port=443): Read timed out. (read timeout=25)
2023-05-09 14:43:10 - Threaded polling exception: A request to the Telegram API was unsuccessful. Error code: 400. Description: Bad Request: message is not modified: specified new message content and reply markup are exactly the same as a current content and reply markup of the message
2023-05-09 14:43:10 - Exception traceback:
Traceback (most recent call last):
  File "/Users/shapovv/PycharmProjects/Radost/venv/lib/python3.9/site-packages/telebot/__init__.py", line 1074, in __threaded_polling
    self.worker_pool.raise_exceptions()
  File "/Users/shapovv/PycharmProjects/Radost/venv/lib/python3.9/site-packages/telebot/util.py", line 147, in raise_exceptions
    raise self.exception_info
  File "/Users/shapovv/PycharmProjects/Radost/venv/lib/python3.9/site-packages/telebot/util.py", line 90, in run
    task(*args, **kwargs)
  File "/Users/shapovv/PycharmProjects/Radost/venv/lib/python3.9/site-packages/telebot/__init__.py", line 6720, in _run_middlewares_and_handler
    result = handler['function'](message)
  File "/Users/shapovv/PycharmProjects/Radost/bot_test.py", line 216, in document_template_handler
    update_document_choice_to_inactive(call.message.chat.id, call.message.message_id)
  File "/Users/shapovv/PycharmProjects/Radost/bot_test.py", line 104, in update_document_choice_to_inactive
    bot.edit_message_reply_markup(chat_id=chat_id, message_id=message_id, reply_markup=keyboard)
  File "/Users/shapovv/PycharmProjects/Radost/venv/lib/python3.9/site-packages/telebot/__init__.py", line 3850, in edit_message_reply_markup
    result = apihelper.edit_message_reply_markup(self.token, chat_id, message_id, inline_message_id, reply_markup)
  File "/Users/shapovv/PycharmProjects/Radost/venv/lib/python3.9/site-packages/telebot/apihelper.py", line 1352, in edit_message_reply_markup
    return _make_request(token, method_url, params=payload, method='post')
  File "/Users/shapovv/PycharmProjects/Radost/venv/lib/python3.9/site-packages/telebot/apihelper.py", line 162, in _make_request
    json_result = _check_result(method_name, result)
  File "/Users/shapovv/PycharmProjects/Radost/venv/lib/python3.9/site-packages/telebot/apihelper.py", line 189, in _check_result
    raise ApiTelegramException(method_name, result, result_json)
telebot.apihelper.ApiTelegramException: A request to the Telegram API was unsuccessful. Error code: 400. Description: Bad Request: message is not modified: specified new message content and reply markup are exactly the same as a current content and reply markup of the message

2023-05-09 14:43:12 - Threaded polling exception: A request to the Telegram API was unsuccessful. Error code: 400. Description: Bad Request: message is not modified: specified new message content and reply markup are exactly the same as a current content and reply markup of the message
2023-05-09 14:43:12 - Exception traceback:
Traceback (most recent call last):
  File "/Users/shapovv/PycharmProjects/Radost/venv/lib/python3.9/site-packages/telebot/__init__.py", line 1074, in __threaded_polling
    self.worker_pool.raise_exceptions()
  File "/Users/shapovv/PycharmProjects/Radost/venv/lib/python3.9/site-packages/telebot/util.py", line 147, in raise_exceptions
    raise self.exception_info
  File "/Users/shapovv/PycharmProjects/Radost/venv/lib/python3.9/site-packages/telebot/util.py", line 90, in run
    task(*args, **kwargs)
  File "/Users/shapovv/PycharmProjects/Radost/venv/lib/python3.9/site-packages/telebot/__init__.py", line 6720, in _run_middlewares_and_handler
    result = handler['function'](message)
  File "/Users/shapovv/PycharmProjects/Radost/bot_test.py", line 216, in document_template_handler
    update_document_choice_to_inactive(call.message.chat.id, call.message.message_id)
  File "/Users/shapovv/PycharmProjects/Radost/bot_test.py", line 104, in update_document_choice_to_inactive
    bot.edit_message_reply_markup(chat_id=chat_id, message_id=message_id, reply_markup=keyboard)
  File "/Users/shapovv/PycharmProjects/Radost/venv/lib/python3.9/site-packages/telebot/__init__.py", line 3850, in edit_message_reply_markup
    result = apihelper.edit_message_reply_markup(self.token, chat_id, message_id, inline_message_id, reply_markup)
  File "/Users/shapovv/PycharmProjects/Radost/venv/lib/python3.9/site-packages/telebot/apihelper.py", line 1352, in edit_message_reply_markup
    return _make_request(token, method_url, params=payload, method='post')
  File "/Users/shapovv/PycharmProjects/Radost/venv/lib/python3.9/site-packages/telebot/apihelper.py", line 162, in _make_request
    json_result = _check_result(method_name, result)
  File "/Users/shapovv/PycharmProjects/Radost/venv/lib/python3.9/site-packages/telebot/apihelper.py", line 189, in _check_result
    raise ApiTelegramException(method_name, result, result_json)
telebot.apihelper.ApiTelegramException: A request to the Telegram API was unsuccessful. Error code: 400. Description: Bad Request: message is not modified: specified new message content and reply markup are exactly the same as a current content and reply markup of the message

2023-05-09 14:43:13 - Threaded polling exception: A request to the Telegram API was unsuccessful. Error code: 400. Description: Bad Request: message is not modified: specified new message content and reply markup are exactly the same as a current content and reply markup of the message
2023-05-09 14:43:13 - Exception traceback:
Traceback (most recent call last):
  File "/Users/shapovv/PycharmProjects/Radost/venv/lib/python3.9/site-packages/telebot/__init__.py", line 1074, in __threaded_polling
    self.worker_pool.raise_exceptions()
  File "/Users/shapovv/PycharmProjects/Radost/venv/lib/python3.9/site-packages/telebot/util.py", line 147, in raise_exceptions
    raise self.exception_info
  File "/Users/shapovv/PycharmProjects/Radost/venv/lib/python3.9/site-packages/telebot/util.py", line 90, in run
    task(*args, **kwargs)
  File "/Users/shapovv/PycharmProjects/Radost/venv/lib/python3.9/site-packages/telebot/__init__.py", line 6720, in _run_middlewares_and_handler
    result = handler['function'](message)
  File "/Users/shapovv/PycharmProjects/Radost/bot_test.py", line 216, in document_template_handler
    update_document_choice_to_inactive(call.message.chat.id, call.message.message_id)
  File "/Users/shapovv/PycharmProjects/Radost/bot_test.py", line 104, in update_document_choice_to_inactive
    bot.edit_message_reply_markup(chat_id=chat_id, message_id=message_id, reply_markup=keyboard)
  File "/Users/shapovv/PycharmProjects/Radost/venv/lib/python3.9/site-packages/telebot/__init__.py", line 3850, in edit_message_reply_markup
    result = apihelper.edit_message_reply_markup(self.token, chat_id, message_id, inline_message_id, reply_markup)
  File "/Users/shapovv/PycharmProjects/Radost/venv/lib/python3.9/site-packages/telebot/apihelper.py", line 1352, in edit_message_reply_markup
    return _make_request(token, method_url, params=payload, method='post')
  File "/Users/shapovv/PycharmProjects/Radost/venv/lib/python3.9/site-packages/telebot/apihelper.py", line 162, in _make_request
    json_result = _check_result(method_name, result)
  File "/Users/shapovv/PycharmProjects/Radost/venv/lib/python3.9/site-packages/telebot/apihelper.py", line 189, in _check_result
    raise ApiTelegramException(method_name, result, result_json)
telebot.apihelper.ApiTelegramException: A request to the Telegram API was unsuccessful. Error code: 400. Description: Bad Request: message is not modified: specified new message content and reply markup are exactly the same as a current content and reply markup of the message

2023-05-09 15:03:42 - Threaded polling exception: A request to the Telegram API was unsuccessful. Error code: 400. Description: Bad Request: can't parse inline keyboard button: Text buttons are unallowed in the inline keyboard
2023-05-09 15:03:42 - Exception traceback:
Traceback (most recent call last):
  File "/Users/shapovv/PycharmProjects/Radost/venv/lib/python3.9/site-packages/telebot/__init__.py", line 1074, in __threaded_polling
    self.worker_pool.raise_exceptions()
  File "/Users/shapovv/PycharmProjects/Radost/venv/lib/python3.9/site-packages/telebot/util.py", line 147, in raise_exceptions
    raise self.exception_info
  File "/Users/shapovv/PycharmProjects/Radost/venv/lib/python3.9/site-packages/telebot/util.py", line 90, in run
    task(*args, **kwargs)
  File "/Users/shapovv/PycharmProjects/Radost/venv/lib/python3.9/site-packages/telebot/__init__.py", line 6720, in _run_middlewares_and_handler
    result = handler['function'](message)
  File "/Users/shapovv/PycharmProjects/Radost/bot_test.py", line 154, in finish_handler
    update_buttons_to_inactive(call.message.chat.id, call.message.message_id, document_type)
  File "/Users/shapovv/PycharmProjects/Radost/bot_test.py", line 143, in update_buttons_to_inactive
    bot.edit_message_text("Что вы хотите сделать дальше?", chat_id=chat_id, message_id=message_id,
  File "/Users/shapovv/PycharmProjects/Radost/venv/lib/python3.9/site-packages/telebot/__init__.py", line 3784, in edit_message_text
    result = apihelper.edit_message_text(self.token, text, chat_id, message_id, inline_message_id, parse_mode,
  File "/Users/shapovv/PycharmProjects/Radost/venv/lib/python3.9/site-packages/telebot/apihelper.py", line 1304, in edit_message_text
    return _make_request(token, method_url, params=payload, method='post')
  File "/Users/shapovv/PycharmProjects/Radost/venv/lib/python3.9/site-packages/telebot/apihelper.py", line 162, in _make_request
    json_result = _check_result(method_name, result)
  File "/Users/shapovv/PycharmProjects/Radost/venv/lib/python3.9/site-packages/telebot/apihelper.py", line 189, in _check_result
    raise ApiTelegramException(method_name, result, result_json)
telebot.apihelper.ApiTelegramException: A request to the Telegram API was unsuccessful. Error code: 400. Description: Bad Request: can't parse inline keyboard button: Text buttons are unallowed in the inline keyboard

2023-05-09 15:58:22 - Threaded polling exception: A request to the Telegram API was unsuccessful. Error code: 400. Description: Bad Request: can't parse entities: Can't find end tag corresponding to start tag b
2023-05-09 15:58:22 - Exception traceback:
Traceback (most recent call last):
  File "/Users/shapovv/PycharmProjects/Radost/venv/lib/python3.9/site-packages/telebot/__init__.py", line 1074, in __threaded_polling
    self.worker_pool.raise_exceptions()
  File "/Users/shapovv/PycharmProjects/Radost/venv/lib/python3.9/site-packages/telebot/util.py", line 147, in raise_exceptions
    raise self.exception_info
  File "/Users/shapovv/PycharmProjects/Radost/venv/lib/python3.9/site-packages/telebot/util.py", line 90, in run
    task(*args, **kwargs)
  File "/Users/shapovv/PycharmProjects/Radost/venv/lib/python3.9/site-packages/telebot/__init__.py", line 6720, in _run_middlewares_and_handler
    result = handler['function'](message)
  File "/Users/shapovv/PycharmProjects/Radost/bot_test.py", line 265, in document_template_handler
    bot.send_message(call.message.chat.id,
  File "/Users/shapovv/PycharmProjects/Radost/venv/lib/python3.9/site-packages/telebot/__init__.py", line 1549, in send_message
    apihelper.send_message(
  File "/Users/shapovv/PycharmProjects/Radost/venv/lib/python3.9/site-packages/telebot/apihelper.py", line 264, in send_message
    return _make_request(token, method_url, params=payload, method='post')
  File "/Users/shapovv/PycharmProjects/Radost/venv/lib/python3.9/site-packages/telebot/apihelper.py", line 162, in _make_request
    json_result = _check_result(method_name, result)
  File "/Users/shapovv/PycharmProjects/Radost/venv/lib/python3.9/site-packages/telebot/apihelper.py", line 189, in _check_result
    raise ApiTelegramException(method_name, result, result_json)
telebot.apihelper.ApiTelegramException: A request to the Telegram API was unsuccessful. Error code: 400. Description: Bad Request: can't parse entities: Can't find end tag corresponding to start tag b

2023-05-09 16:12:27 - Error: 760923861
2023-05-09 16:20:04 - Error: 'NoneType' object has no attribute 'startswith'
2023-05-09 23:53:49 - Threaded polling exception: A request to the Telegram API was unsuccessful. Error code: 400. Description: Bad Request: can't parse entities: Unsupported start tag "b/" at byte offset 95
2023-05-09 23:53:49 - Exception traceback:
Traceback (most recent call last):
  File "/Users/shapovv/PycharmProjects/Radost/venv/lib/python3.9/site-packages/telebot/__init__.py", line 1074, in __threaded_polling
    self.worker_pool.raise_exceptions()
  File "/Users/shapovv/PycharmProjects/Radost/venv/lib/python3.9/site-packages/telebot/util.py", line 147, in raise_exceptions
    raise self.exception_info
  File "/Users/shapovv/PycharmProjects/Radost/venv/lib/python3.9/site-packages/telebot/util.py", line 90, in run
    task(*args, **kwargs)
  File "/Users/shapovv/PycharmProjects/Radost/venv/lib/python3.9/site-packages/telebot/__init__.py", line 6720, in _run_middlewares_and_handler
    result = handler['function'](message)
  File "/Users/shapovv/PycharmProjects/Radost/bot_test.py", line 277, in document_template_handler
    bot.send_message(call.message.chat.id,
  File "/Users/shapovv/PycharmProjects/Radost/venv/lib/python3.9/site-packages/telebot/__init__.py", line 1549, in send_message
    apihelper.send_message(
  File "/Users/shapovv/PycharmProjects/Radost/venv/lib/python3.9/site-packages/telebot/apihelper.py", line 264, in send_message
    return _make_request(token, method_url, params=payload, method='post')
  File "/Users/shapovv/PycharmProjects/Radost/venv/lib/python3.9/site-packages/telebot/apihelper.py", line 162, in _make_request
    json_result = _check_result(method_name, result)
  File "/Users/shapovv/PycharmProjects/Radost/venv/lib/python3.9/site-packages/telebot/apihelper.py", line 189, in _check_result
    raise ApiTelegramException(method_name, result, result_json)
telebot.apihelper.ApiTelegramException: A request to the Telegram API was unsuccessful. Error code: 400. Description: Bad Request: can't parse entities: Unsupported start tag "b/" at byte offset 95

2023-05-10 13:43:37 - Error: HTTPSConnectionPool(host='api.telegram.org', port=443): Read timed out. (read timeout=25)
2023-05-10 13:50:55 - Error: HTTPSConnectionPool(host='api.telegram.org', port=443): Read timed out. (read timeout=25)
2023-05-10 15:24:04 - Error: keywords must be strings
2023-05-10 15:24:14 - Error: keywords must be strings
2023-05-10 15:45:00 - Error: [Errno 2] No such file or directory: 'output_files/title_page_Shapovalov_2023.docx'
2023-05-10 15:47:44 - Error: [Errno 2] No such file or directory: 'output_files/title_page_shap_2023.docx'
2023-05-10 15:51:19 - Error: [Errno 2] No such file or directory: 'output_files/title_page_Shapovv_2023.docx'
2023-05-10 15:51:30 - Error: [Errno 2] No such file or directory: 'output_files/title_page_Shapovv_2023.docx'
2023-05-10 15:55:38 - Error: [Errno 2] No such file or directory: 'output_files/title_page_shapovv_2023.pdf'
2023-05-10 15:55:49 - Error: [Errno 2] No such file or directory: 'output_files/title_page_shapovv_2023.pdf'
2023-05-10 16:00:38 - Error: [Errno 2] No such file or directory: 'output_files/title_page_Osip_2025.pdf'
2023-05-10 16:00:48 - Error: [Errno 2] No such file or directory: 'output_files/title_page_Osip_2025.pdf'
2023-05-10 16:00:58 - Error: [Errno 2] No such file or directory: 'output_files/title_page_Osip_2025.pdf'
2023-05-10 16:01:09 - Error: [Errno 2] No such file or directory: 'output_files/title_page_Osip_2025.pdf'
2023-05-10 16:01:29 - Error: [Errno 2] No such file or directory: 'output_files/title_page_Osip_2025.pdf'
2023-05-10 16:28:19 - Error: HTTPSConnectionPool(host='api.telegram.org', port=443): Read timed out. (read timeout=25)
2023-05-10 16:47:23 - Error: 760923861
2023-05-10 18:12:46 - Error: Тестовое исключение
2023-05-10 18:54:47 - Threaded polling exception: A request to the Telegram API was unsuccessful. Error code: 400. Description: Bad Request: BUTTON_DATA_INVALID
2023-05-10 18:54:47 - Exception traceback:
Traceback (most recent call last):
  File "/Users/shapovv/PycharmProjects/Radost/venv/lib/python3.9/site-packages/telebot/__init__.py", line 1074, in __threaded_polling
    self.worker_pool.raise_exceptions()
  File "/Users/shapovv/PycharmProjects/Radost/venv/lib/python3.9/site-packages/telebot/util.py", line 147, in raise_exceptions
    raise self.exception_info
  File "/Users/shapovv/PycharmProjects/Radost/venv/lib/python3.9/site-packages/telebot/util.py", line 90, in run
    task(*args, **kwargs)
  File "/Users/shapovv/PycharmProjects/Radost/bot_test.py", line 56, in save_handler
    next_step_handler(message, chat_steps[message.chat.id])
  File "/Users/shapovv/PycharmProjects/Radost/bot_test.py", line 93, in next_step_handler
    create_document(message, explanatory_note_code_blocks[message.chat.id], 'explanatory_note_maket.docx',
  File "/Users/shapovv/PycharmProjects/Radost/bot_test.py", line 275, in create_document
    ask_for_conversion(message, filename)
  File "/Users/shapovv/PycharmProjects/Radost/bot_test.py", line 209, in ask_for_conversion
    bot.send_message(message.chat.id, 'Хотите конвертировать файл в формат PDF?', reply_markup=markup)
  File "/Users/shapovv/PycharmProjects/Radost/venv/lib/python3.9/site-packages/telebot/__init__.py", line 1549, in send_message
    apihelper.send_message(
  File "/Users/shapovv/PycharmProjects/Radost/venv/lib/python3.9/site-packages/telebot/apihelper.py", line 264, in send_message
    return _make_request(token, method_url, params=payload, method='post')
  File "/Users/shapovv/PycharmProjects/Radost/venv/lib/python3.9/site-packages/telebot/apihelper.py", line 162, in _make_request
    json_result = _check_result(method_name, result)
  File "/Users/shapovv/PycharmProjects/Radost/venv/lib/python3.9/site-packages/telebot/apihelper.py", line 189, in _check_result
    raise ApiTelegramException(method_name, result, result_json)
telebot.apihelper.ApiTelegramException: A request to the Telegram API was unsuccessful. Error code: 400. Description: Bad Request: BUTTON_DATA_INVALID

2023-05-10 19:09:07 - Threaded polling exception: A request to the Telegram API was unsuccessful. Error code: 400. Description: Bad Request: BUTTON_DATA_INVALID
2023-05-10 19:09:07 - Exception traceback:
Traceback (most recent call last):
  File "/Users/shapovv/PycharmProjects/Radost/venv/lib/python3.9/site-packages/telebot/__init__.py", line 1074, in __threaded_polling
    self.worker_pool.raise_exceptions()
  File "/Users/shapovv/PycharmProjects/Radost/venv/lib/python3.9/site-packages/telebot/util.py", line 147, in raise_exceptions
    raise self.exception_info
  File "/Users/shapovv/PycharmProjects/Radost/venv/lib/python3.9/site-packages/telebot/util.py", line 90, in run
    task(*args, **kwargs)
  File "/Users/shapovv/PycharmProjects/Radost/bot_test.py", line 56, in save_handler
    next_step_handler(message, chat_steps[message.chat.id])
  File "/Users/shapovv/PycharmProjects/Radost/bot_test.py", line 93, in next_step_handler
    create_document(message, explanatory_note_code_blocks[message.chat.id], 'explanatory_note_maket.docx',
  File "/Users/shapovv/PycharmProjects/Radost/bot_test.py", line 274, in create_document
    ask_for_conversion(message, filename)
  File "/Users/shapovv/PycharmProjects/Radost/bot_test.py", line 208, in ask_for_conversion
    bot.send_message(message.chat.id, 'Хотите конвертировать файл в формат PDF?', reply_markup=markup)
  File "/Users/shapovv/PycharmProjects/Radost/venv/lib/python3.9/site-packages/telebot/__init__.py", line 1549, in send_message
    apihelper.send_message(
  File "/Users/shapovv/PycharmProjects/Radost/venv/lib/python3.9/site-packages/telebot/apihelper.py", line 264, in send_message
    return _make_request(token, method_url, params=payload, method='post')
  File "/Users/shapovv/PycharmProjects/Radost/venv/lib/python3.9/site-packages/telebot/apihelper.py", line 162, in _make_request
    json_result = _check_result(method_name, result)
  File "/Users/shapovv/PycharmProjects/Radost/venv/lib/python3.9/site-packages/telebot/apihelper.py", line 189, in _check_result
    raise ApiTelegramException(method_name, result, result_json)
telebot.apihelper.ApiTelegramException: A request to the Telegram API was unsuccessful. Error code: 400. Description: Bad Request: BUTTON_DATA_INVALID

2023-05-10 19:09:54 - Error: [Errno 2] No such file or directory: 'output_files/explanatory_note_yak_2020.pdf'
2023-05-10 19:10:21 - Error: [Errno 2] No such file or directory: 'output_files/explanatory_note_yak_2020.pdf'
2023-05-10 19:46:43 - Threaded polling exception: A request to the Telegram API was unsuccessful. Error code: 400. Description: Bad Request: BUTTON_DATA_INVALID
2023-05-10 19:46:43 - Exception traceback:
Traceback (most recent call last):
  File "/Users/shapovv/PycharmProjects/Radost/venv/lib/python3.9/site-packages/telebot/__init__.py", line 1074, in __threaded_polling
    self.worker_pool.raise_exceptions()
  File "/Users/shapovv/PycharmProjects/Radost/venv/lib/python3.9/site-packages/telebot/util.py", line 147, in raise_exceptions
    raise self.exception_info
  File "/Users/shapovv/PycharmProjects/Radost/venv/lib/python3.9/site-packages/telebot/util.py", line 90, in run
    task(*args, **kwargs)
  File "/Users/shapovv/PycharmProjects/Radost/bot_test.py", line 50, in save_handler
    handle_stop(message)
  File "/Users/shapovv/PycharmProjects/Radost/bot_test.py", line 302, in handle_stop
    create_document(message, explanatory_note_code_blocks[message.chat.id], 'explanatory_note_maket.docx',
  File "/Users/shapovv/PycharmProjects/Radost/bot_test.py", line 280, in create_document
    ask_for_conversion(message, filename)
  File "/Users/shapovv/PycharmProjects/Radost/bot_test.py", line 214, in ask_for_conversion
    bot.send_message(message.chat.id, 'Хотите конвертировать файл в формат PDF?', reply_markup=markup)
  File "/Users/shapovv/PycharmProjects/Radost/venv/lib/python3.9/site-packages/telebot/__init__.py", line 1549, in send_message
    apihelper.send_message(
  File "/Users/shapovv/PycharmProjects/Radost/venv/lib/python3.9/site-packages/telebot/apihelper.py", line 264, in send_message
    return _make_request(token, method_url, params=payload, method='post')
  File "/Users/shapovv/PycharmProjects/Radost/venv/lib/python3.9/site-packages/telebot/apihelper.py", line 162, in _make_request
    json_result = _check_result(method_name, result)
  File "/Users/shapovv/PycharmProjects/Radost/venv/lib/python3.9/site-packages/telebot/apihelper.py", line 189, in _check_result
    raise ApiTelegramException(method_name, result, result_json)
telebot.apihelper.ApiTelegramException: A request to the Telegram API was unsuccessful. Error code: 400. Description: Bad Request: BUTTON_DATA_INVALID

2023-05-10 22:23:26 - Threaded polling exception: A request to the Telegram API was unsuccessful. Error code: 400. Description: Bad Request: BUTTON_DATA_INVALID
2023-05-10 22:23:26 - Exception traceback:
Traceback (most recent call last):
  File "/Users/shapovv/PycharmProjects/Radost/venv/lib/python3.9/site-packages/telebot/__init__.py", line 1074, in __threaded_polling
    self.worker_pool.raise_exceptions()
  File "/Users/shapovv/PycharmProjects/Radost/venv/lib/python3.9/site-packages/telebot/util.py", line 147, in raise_exceptions
    raise self.exception_info
  File "/Users/shapovv/PycharmProjects/Radost/venv/lib/python3.9/site-packages/telebot/util.py", line 90, in run
    task(*args, **kwargs)
  File "/Users/shapovv/PycharmProjects/Radost/bot_test.py", line 59, in save_handler
    next_step_handler(message, chat_steps[message.chat.id])
  File "/Users/shapovv/PycharmProjects/Radost/bot_test.py", line 96, in next_step_handler
    create_document(message, explanatory_note_code_blocks[message.chat.id], 'explanatory_note_maket.docx',
  File "/Users/shapovv/PycharmProjects/Radost/bot_test.py", line 288, in create_document
    ask_for_conversion(message, filename)
  File "/Users/shapovv/PycharmProjects/Radost/bot_test.py", line 217, in ask_for_conversion
    bot.send_message(message.chat.id,
  File "/Users/shapovv/PycharmProjects/Radost/venv/lib/python3.9/site-packages/telebot/__init__.py", line 1549, in send_message
    apihelper.send_message(
  File "/Users/shapovv/PycharmProjects/Radost/venv/lib/python3.9/site-packages/telebot/apihelper.py", line 264, in send_message
    return _make_request(token, method_url, params=payload, method='post')
  File "/Users/shapovv/PycharmProjects/Radost/venv/lib/python3.9/site-packages/telebot/apihelper.py", line 162, in _make_request
    json_result = _check_result(method_name, result)
  File "/Users/shapovv/PycharmProjects/Radost/venv/lib/python3.9/site-packages/telebot/apihelper.py", line 189, in _check_result
    raise ApiTelegramException(method_name, result, result_json)
telebot.apihelper.ApiTelegramException: A request to the Telegram API was unsuccessful. Error code: 400. Description: Bad Request: BUTTON_DATA_INVALID

2023-05-10 22:38:07 - Threaded polling exception: A request to the Telegram API was unsuccessful. Error code: 400. Description: Bad Request: BUTTON_DATA_INVALID
2023-05-10 22:38:07 - Exception traceback:
Traceback (most recent call last):
  File "/Users/shapovv/PycharmProjects/Radost/venv/lib/python3.9/site-packages/telebot/__init__.py", line 1074, in __threaded_polling
    self.worker_pool.raise_exceptions()
  File "/Users/shapovv/PycharmProjects/Radost/venv/lib/python3.9/site-packages/telebot/util.py", line 147, in raise_exceptions
    raise self.exception_info
  File "/Users/shapovv/PycharmProjects/Radost/venv/lib/python3.9/site-packages/telebot/util.py", line 90, in run
    task(*args, **kwargs)
  File "/Users/shapovv/PycharmProjects/Radost/bot_test.py", line 58, in save_handler
    next_step_handler(message, chat_steps[message.chat.id])
  File "/Users/shapovv/PycharmProjects/Radost/bot_test.py", line 95, in next_step_handler
    create_document(message, explanatory_note_code_blocks[message.chat.id], 'explanatory_note_maket.docx',
  File "/Users/shapovv/PycharmProjects/Radost/bot_test.py", line 283, in create_document
    ask_for_conversion(message, filename)
  File "/Users/shapovv/PycharmProjects/Radost/bot_test.py", line 212, in ask_for_conversion
    bot.send_message(message.chat.id,
  File "/Users/shapovv/PycharmProjects/Radost/venv/lib/python3.9/site-packages/telebot/__init__.py", line 1549, in send_message
    apihelper.send_message(
  File "/Users/shapovv/PycharmProjects/Radost/venv/lib/python3.9/site-packages/telebot/apihelper.py", line 264, in send_message
    return _make_request(token, method_url, params=payload, method='post')
  File "/Users/shapovv/PycharmProjects/Radost/venv/lib/python3.9/site-packages/telebot/apihelper.py", line 162, in _make_request
    json_result = _check_result(method_name, result)
  File "/Users/shapovv/PycharmProjects/Radost/venv/lib/python3.9/site-packages/telebot/apihelper.py", line 189, in _check_result
    raise ApiTelegramException(method_name, result, result_json)
telebot.apihelper.ApiTelegramException: A request to the Telegram API was unsuccessful. Error code: 400. Description: Bad Request: BUTTON_DATA_INVALID

2023-05-10 22:47:56 - Threaded polling exception: A request to the Telegram API was unsuccessful. Error code: 400. Description: Bad Request: BUTTON_DATA_INVALID
2023-05-10 22:47:56 - Exception traceback:
Traceback (most recent call last):
  File "/Users/shapovv/PycharmProjects/Radost/venv/lib/python3.9/site-packages/telebot/__init__.py", line 1074, in __threaded_polling
    self.worker_pool.raise_exceptions()
  File "/Users/shapovv/PycharmProjects/Radost/venv/lib/python3.9/site-packages/telebot/util.py", line 147, in raise_exceptions
    raise self.exception_info
  File "/Users/shapovv/PycharmProjects/Radost/venv/lib/python3.9/site-packages/telebot/util.py", line 90, in run
    task(*args, **kwargs)
  File "/Users/shapovv/PycharmProjects/Radost/bot_test.py", line 58, in save_handler
    next_step_handler(message, chat_steps[message.chat.id])
  File "/Users/shapovv/PycharmProjects/Radost/bot_test.py", line 95, in next_step_handler
    create_document(message, explanatory_note_code_blocks[message.chat.id], 'explanatory_note_maket.docx',
  File "/Users/shapovv/PycharmProjects/Radost/bot_test.py", line 284, in create_document
    ask_for_conversion(message, filename)
  File "/Users/shapovv/PycharmProjects/Radost/bot_test.py", line 212, in ask_for_conversion
    bot.send_message(message.chat.id,
  File "/Users/shapovv/PycharmProjects/Radost/venv/lib/python3.9/site-packages/telebot/__init__.py", line 1549, in send_message
    apihelper.send_message(
  File "/Users/shapovv/PycharmProjects/Radost/venv/lib/python3.9/site-packages/telebot/apihelper.py", line 264, in send_message
    return _make_request(token, method_url, params=payload, method='post')
  File "/Users/shapovv/PycharmProjects/Radost/venv/lib/python3.9/site-packages/telebot/apihelper.py", line 162, in _make_request
    json_result = _check_result(method_name, result)
  File "/Users/shapovv/PycharmProjects/Radost/venv/lib/python3.9/site-packages/telebot/apihelper.py", line 189, in _check_result
    raise ApiTelegramException(method_name, result, result_json)
telebot.apihelper.ApiTelegramException: A request to the Telegram API was unsuccessful. Error code: 400. Description: Bad Request: BUTTON_DATA_INVALID

2023-05-10 22:48:55 - Threaded polling exception: A request to the Telegram API was unsuccessful. Error code: 400. Description: Bad Request: BUTTON_DATA_INVALID
2023-05-10 22:48:55 - Exception traceback:
Traceback (most recent call last):
  File "/Users/shapovv/PycharmProjects/Radost/venv/lib/python3.9/site-packages/telebot/__init__.py", line 1074, in __threaded_polling
    self.worker_pool.raise_exceptions()
  File "/Users/shapovv/PycharmProjects/Radost/venv/lib/python3.9/site-packages/telebot/util.py", line 147, in raise_exceptions
    raise self.exception_info
  File "/Users/shapovv/PycharmProjects/Radost/venv/lib/python3.9/site-packages/telebot/util.py", line 90, in run
    task(*args, **kwargs)
  File "/Users/shapovv/PycharmProjects/Radost/venv/lib/python3.9/site-packages/telebot/__init__.py", line 6720, in _run_middlewares_and_handler
    result = handler['function'](message)
  File "/Users/shapovv/PycharmProjects/Radost/bot_test.py", line 373, in handle_stop_command
    handle_stop(message)
  File "/Users/shapovv/PycharmProjects/Radost/bot_test.py", line 306, in handle_stop
    create_document(message, explanatory_note_code_blocks[message.chat.id], 'explanatory_note_maket.docx',
  File "/Users/shapovv/PycharmProjects/Radost/bot_test.py", line 284, in create_document
    ask_for_conversion(message, filename)
  File "/Users/shapovv/PycharmProjects/Radost/bot_test.py", line 212, in ask_for_conversion
    bot.send_message(message.chat.id,
  File "/Users/shapovv/PycharmProjects/Radost/venv/lib/python3.9/site-packages/telebot/__init__.py", line 1549, in send_message
    apihelper.send_message(
  File "/Users/shapovv/PycharmProjects/Radost/venv/lib/python3.9/site-packages/telebot/apihelper.py", line 264, in send_message
    return _make_request(token, method_url, params=payload, method='post')
  File "/Users/shapovv/PycharmProjects/Radost/venv/lib/python3.9/site-packages/telebot/apihelper.py", line 162, in _make_request
    json_result = _check_result(method_name, result)
  File "/Users/shapovv/PycharmProjects/Radost/venv/lib/python3.9/site-packages/telebot/apihelper.py", line 189, in _check_result
    raise ApiTelegramException(method_name, result, result_json)
telebot.apihelper.ApiTelegramException: A request to the Telegram API was unsuccessful. Error code: 400. Description: Bad Request: BUTTON_DATA_INVALID

2023-05-10 22:49:42 - Threaded polling exception: A request to the Telegram API was unsuccessful. Error code: 400. Description: Bad Request: BUTTON_DATA_INVALID
2023-05-10 22:49:42 - Exception traceback:
Traceback (most recent call last):
  File "/Users/shapovv/PycharmProjects/Radost/venv/lib/python3.9/site-packages/telebot/__init__.py", line 1074, in __threaded_polling
    self.worker_pool.raise_exceptions()
  File "/Users/shapovv/PycharmProjects/Radost/venv/lib/python3.9/site-packages/telebot/util.py", line 147, in raise_exceptions
    raise self.exception_info
  File "/Users/shapovv/PycharmProjects/Radost/venv/lib/python3.9/site-packages/telebot/util.py", line 90, in run
    task(*args, **kwargs)
  File "/Users/shapovv/PycharmProjects/Radost/bot_test.py", line 58, in save_handler
    next_step_handler(message, chat_steps[message.chat.id])
  File "/Users/shapovv/PycharmProjects/Radost/bot_test.py", line 95, in next_step_handler
    create_document(message, explanatory_note_code_blocks[message.chat.id], 'explanatory_note_maket.docx',
  File "/Users/shapovv/PycharmProjects/Radost/bot_test.py", line 284, in create_document
    ask_for_conversion(message, filename)
  File "/Users/shapovv/PycharmProjects/Radost/bot_test.py", line 212, in ask_for_conversion
    bot.send_message(message.chat.id,
  File "/Users/shapovv/PycharmProjects/Radost/venv/lib/python3.9/site-packages/telebot/__init__.py", line 1549, in send_message
    apihelper.send_message(
  File "/Users/shapovv/PycharmProjects/Radost/venv/lib/python3.9/site-packages/telebot/apihelper.py", line 264, in send_message
    return _make_request(token, method_url, params=payload, method='post')
  File "/Users/shapovv/PycharmProjects/Radost/venv/lib/python3.9/site-packages/telebot/apihelper.py", line 162, in _make_request
    json_result = _check_result(method_name, result)
  File "/Users/shapovv/PycharmProjects/Radost/venv/lib/python3.9/site-packages/telebot/apihelper.py", line 189, in _check_result
    raise ApiTelegramException(method_name, result, result_json)
telebot.apihelper.ApiTelegramException: A request to the Telegram API was unsuccessful. Error code: 400. Description: Bad Request: BUTTON_DATA_INVALID

2023-05-11 00:35:30 - Error: 'NoneType' object has no attribute 'startswith'
